2017-03-25 11:22:56,426 [Thread-12:123145540919296] [django.template:927] [base:_resolve_lookup] [DEBUG]- Exception while resolving variable 'is_popup' in template 'admin/index.html'.
Traceback (most recent call last):
  File "/workspace/python/django_blog_venv/lib/python3.6/site-packages/django/template/base.py", line 883, in _resolve_lookup
    current = current[bit]
  File "/workspace/python/django_blog_venv/lib/python3.6/site-packages/django/template/context.py", line 77, in __getitem__
    raise KeyError(key)
KeyError: 'is_popup'

During handling of the above exception, another exception occurred:

Traceback (most recent call last):
  File "/workspace/python/django_blog_venv/lib/python3.6/site-packages/django/template/base.py", line 889, in _resolve_lookup
    if isinstance(current, BaseContext) and getattr(type(current), bit):
AttributeError: type object 'RequestContext' has no attribute 'is_popup'

During handling of the above exception, another exception occurred:

Traceback (most recent call last):
  File "/workspace/python/django_blog_venv/lib/python3.6/site-packages/django/template/base.py", line 898, in _resolve_lookup
    current = current[int(bit)]
ValueError: invalid literal for int() with base 10: 'is_popup'

During handling of the above exception, another exception occurred:

Traceback (most recent call last):
  File "/workspace/python/django_blog_venv/lib/python3.6/site-packages/django/template/base.py", line 905, in _resolve_lookup
    (bit, current))  # missing attribute
django.template.base.VariableDoesNotExist: Failed lookup for key [is_popup] in "[{'True': True, 'False': False, 'None': None}, {'csrf_token': <SimpleLazyObject: <function csrf.<locals>._get_val at 0x108b01f28>>, 'request': <WSGIRequest: GET '/admin/'>, 'user': <SimpleLazyObject: <User: admin>>, 'perms': <django.contrib.auth.context_processors.PermWrapper object at 0x108acbc18>, 'messages': <django.contrib.messages.storage.fallback.FallbackStorage object at 0x108980c88>, 'DEFAULT_MESSAGE_LEVELS': {'DEBUG': 10, 'INFO': 20, 'SUCCESS': 25, 'WARNING': 30, 'ERROR': 40}, 'recommended_list': [], 'article_comment_list': [<Article: The Day you went away>, <Article: 男人海洋>, <Article: 海浪>], 'comment_count_list': [{'article': 7, 'comment_count': 4}, {'article': 3, 'comment_count': 1}, {'article': 5, 'comment_count': 1}], 'viewed_count_list': [<Article: 倩女幽魂>, <Article: 黄昏>, <Article: 男人海洋>, <Article: 海浪>, <Article: 记事本>, <Article: 静夜思>], 'tag_list': [<Tag: 古诗>, <Tag: 唐代>, <Tag: 歌词>], 'archive_list': ['2017年03月文章归档', '2017年02月文章归档', '2017年01月文章归档'], 'category_list': [<Category: 编程>, <Category: 摄影>, <Category: 书法>, <Category: 古诗词>, <Category: 歌词>], 'SITE_URL': 'localhost:8000/', 'SITE_DESC': '学无先后，达者为师', 'SITE_NAME': '沉默的个人博客'}, {}, {'site_title': <django.utils.functional.lazy.<locals>.__proxy__ object at 0x10834fda0>, 'site_header': <django.utils.functional.lazy.<locals>.__proxy__ object at 0x10834fe10>, 'site_url': '/', 'has_permission': True, 'available_apps': [{'name': <django.utils.functional.lazy.<locals>.__proxy__ object at 0x108360908>, 'app_label': 'auth', 'app_url': '/admin/auth/', 'has_module_perms': True, 'models': [{'name': <django.utils.functional.lazy.<locals>.__proxy__ object at 0x108980a58>, 'object_name': 'Group', 'perms': {'add': True, 'change': True, 'delete': True}, 'admin_url': '/admin/auth/group/', 'add_url': '/admin/auth/group/add/'}]}, {'name': 'Blog', 'app_label': 'blog', 'app_url': '/admin/blog/', 'has_module_perms': True, 'models': [{'name': '分类', 'object_name': 'Category', 'perms': {'add': True, 'change': True, 'delete': True}, 'admin_url': '/admin/blog/category/', 'add_url': '/admin/blog/category/add/'}, {'name': '友情链接', 'object_name': 'Links', 'perms': {'add': True, 'change': True, 'delete': True}, 'admin_url': '/admin/blog/links/', 'add_url': '/admin/blog/links/add/'}, {'name': '广告', 'object_name': 'Ad', 'perms': {'add': True, 'change': True, 'delete': True}, 'admin_url': '/admin/blog/ad/', 'add_url': '/admin/blog/ad/add/'}, {'name': '文章', 'object_name': 'Article', 'perms': {'add': True, 'change': True, 'delete': True}, 'admin_url': '/admin/blog/article/', 'add_url': '/admin/blog/article/add/'}, {'name': '标签', 'object_name': 'Tag', 'perms': {'add': True, 'change': True, 'delete': True}, 'admin_url': '/admin/blog/tag/', 'add_url': '/admin/blog/tag/add/'}, {'name': '用户', 'object_name': 'User', 'perms': {'add': True, 'change': True, 'delete': True}, 'admin_url': '/admin/blog/user/', 'add_url': '/admin/blog/user/add/'}, {'name': '评论', 'object_name': 'Comment', 'perms': {'add': True, 'change': True, 'delete': True}, 'admin_url': '/admin/blog/comment/', 'add_url': '/admin/blog/comment/add/'}]}], 'title': <django.utils.functional.lazy.<locals>.__proxy__ object at 0x108360358>, 'app_list': [{'name': <django.utils.functional.lazy.<locals>.__proxy__ object at 0x108360908>, 'app_label': 'auth', 'app_url': '/admin/auth/', 'has_module_perms': True, 'models': [{'name': <django.utils.functional.lazy.<locals>.__proxy__ object at 0x108980c50>, 'object_name': 'Group', 'perms': {'add': True, 'change': True, 'delete': True}, 'admin_url': '/admin/auth/group/', 'add_url': '/admin/auth/group/add/'}]}, {'name': 'Blog', 'app_label': 'blog', 'app_url': '/admin/blog/', 'has_module_perms': True, 'models': [{'name': '分类', 'object_name': 'Category', 'perms': {'add': True, 'change': True, 'delete': True}, 'admin_url': '/admin/blog/category/', 'add_url': '/admin/blog/category/add/'}, {'name': '友情链接', 'object_name': 'Links', 'perms': {'add': True, 'change': True, 'delete': True}, 'admin_url': '/admin/blog/links/', 'add_url': '/admin/blog/links/add/'}, {'name': '广告', 'object_name': 'Ad', 'perms': {'add': True, 'change': True, 'delete': True}, 'admin_url': '/admin/blog/ad/', 'add_url': '/admin/blog/ad/add/'}, {'name': '文章', 'object_name': 'Article', 'perms': {'add': True, 'change': True, 'delete': True}, 'admin_url': '/admin/blog/article/', 'add_url': '/admin/blog/article/add/'}, {'name': '标签', 'object_name': 'Tag', 'perms': {'add': True, 'change': True, 'delete': True}, 'admin_url': '/admin/blog/tag/', 'add_url': '/admin/blog/tag/add/'}, {'name': '用户', 'object_name': 'User', 'perms': {'add': True, 'change': True, 'delete': True}, 'admin_url': '/admin/blog/user/', 'add_url': '/admin/blog/user/add/'}, {'name': '评论', 'object_name': 'Comment', 'perms': {'add': True, 'change': True, 'delete': True}, 'admin_url': '/admin/blog/comment/', 'add_url': '/admin/blog/comment/add/'}]}], 'LANGUAGE_CODE': 'en-us', 'LANGUAGE_BIDI': False}]"
2017-03-25 18:35:55,913 [Thread-2:123145563934720] [django.template:927] [base:_resolve_lookup] [DEBUG]- Exception while resolving variable 'year' in template 'index.html'.
Traceback (most recent call last):
  File "/workspace/python/django_blog_venv/lib/python3.6/site-packages/django/utils/datastructures.py", line 83, in __getitem__
    list_ = super(MultiValueDict, self).__getitem__(key)
KeyError: 'year'

During handling of the above exception, another exception occurred:

Traceback (most recent call last):
  File "/workspace/python/django_blog_venv/lib/python3.6/site-packages/django/template/base.py", line 883, in _resolve_lookup
    current = current[bit]
  File "/workspace/python/django_blog_venv/lib/python3.6/site-packages/django/utils/datastructures.py", line 85, in __getitem__
    raise MultiValueDictKeyError(repr(key))
django.utils.datastructures.MultiValueDictKeyError: "'year'"

During handling of the above exception, another exception occurred:

Traceback (most recent call last):
  File "/workspace/python/django_blog_venv/lib/python3.6/site-packages/django/template/base.py", line 891, in _resolve_lookup
    current = getattr(current, bit)
AttributeError: 'QueryDict' object has no attribute 'year'

During handling of the above exception, another exception occurred:

Traceback (most recent call last):
  File "/workspace/python/django_blog_venv/lib/python3.6/site-packages/django/template/base.py", line 898, in _resolve_lookup
    current = current[int(bit)]
ValueError: invalid literal for int() with base 10: 'year'

During handling of the above exception, another exception occurred:

Traceback (most recent call last):
  File "/workspace/python/django_blog_venv/lib/python3.6/site-packages/django/template/base.py", line 905, in _resolve_lookup
    (bit, current))  # missing attribute
django.template.base.VariableDoesNotExist: Failed lookup for key [year] in '<QueryDict: {}>'
2017-03-25 18:35:55,915 [Thread-2:123145563934720] [django.template:927] [base:_resolve_lookup] [DEBUG]- Exception while resolving variable 'month' in template 'index.html'.
Traceback (most recent call last):
  File "/workspace/python/django_blog_venv/lib/python3.6/site-packages/django/utils/datastructures.py", line 83, in __getitem__
    list_ = super(MultiValueDict, self).__getitem__(key)
KeyError: 'month'

During handling of the above exception, another exception occurred:

Traceback (most recent call last):
  File "/workspace/python/django_blog_venv/lib/python3.6/site-packages/django/template/base.py", line 883, in _resolve_lookup
    current = current[bit]
  File "/workspace/python/django_blog_venv/lib/python3.6/site-packages/django/utils/datastructures.py", line 85, in __getitem__
    raise MultiValueDictKeyError(repr(key))
django.utils.datastructures.MultiValueDictKeyError: "'month'"

During handling of the above exception, another exception occurred:

Traceback (most recent call last):
  File "/workspace/python/django_blog_venv/lib/python3.6/site-packages/django/template/base.py", line 891, in _resolve_lookup
    current = getattr(current, bit)
AttributeError: 'QueryDict' object has no attribute 'month'

During handling of the above exception, another exception occurred:

Traceback (most recent call last):
  File "/workspace/python/django_blog_venv/lib/python3.6/site-packages/django/template/base.py", line 898, in _resolve_lookup
    current = current[int(bit)]
ValueError: invalid literal for int() with base 10: 'month'

During handling of the above exception, another exception occurred:

Traceback (most recent call last):
  File "/workspace/python/django_blog_venv/lib/python3.6/site-packages/django/template/base.py", line 905, in _resolve_lookup
    (bit, current))  # missing attribute
django.template.base.VariableDoesNotExist: Failed lookup for key [month] in '<QueryDict: {}>'
2017-03-25 18:35:55,916 [Thread-2:123145563934720] [django.template:927] [base:_resolve_lookup] [DEBUG]- Exception while resolving variable 'cid' in template 'index.html'.
Traceback (most recent call last):
  File "/workspace/python/django_blog_venv/lib/python3.6/site-packages/django/utils/datastructures.py", line 83, in __getitem__
    list_ = super(MultiValueDict, self).__getitem__(key)
KeyError: 'cid'

During handling of the above exception, another exception occurred:

Traceback (most recent call last):
  File "/workspace/python/django_blog_venv/lib/python3.6/site-packages/django/template/base.py", line 883, in _resolve_lookup
    current = current[bit]
  File "/workspace/python/django_blog_venv/lib/python3.6/site-packages/django/utils/datastructures.py", line 85, in __getitem__
    raise MultiValueDictKeyError(repr(key))
django.utils.datastructures.MultiValueDictKeyError: "'cid'"

During handling of the above exception, another exception occurred:

Traceback (most recent call last):
  File "/workspace/python/django_blog_venv/lib/python3.6/site-packages/django/template/base.py", line 891, in _resolve_lookup
    current = getattr(current, bit)
AttributeError: 'QueryDict' object has no attribute 'cid'

During handling of the above exception, another exception occurred:

Traceback (most recent call last):
  File "/workspace/python/django_blog_venv/lib/python3.6/site-packages/django/template/base.py", line 898, in _resolve_lookup
    current = current[int(bit)]
ValueError: invalid literal for int() with base 10: 'cid'

During handling of the above exception, another exception occurred:

Traceback (most recent call last):
  File "/workspace/python/django_blog_venv/lib/python3.6/site-packages/django/template/base.py", line 905, in _resolve_lookup
    (bit, current))  # missing attribute
django.template.base.VariableDoesNotExist: Failed lookup for key [cid] in '<QueryDict: {}>'
2017-03-25 18:56:00,754 [Thread-4:123145393901568] [django.template:927] [base:_resolve_lookup] [DEBUG]- Exception while resolving variable 'year' in template 'index.html'.
Traceback (most recent call last):
  File "/workspace/python/django_blog_venv/lib/python3.6/site-packages/django/utils/datastructures.py", line 83, in __getitem__
    list_ = super(MultiValueDict, self).__getitem__(key)
KeyError: 'year'

During handling of the above exception, another exception occurred:

Traceback (most recent call last):
  File "/workspace/python/django_blog_venv/lib/python3.6/site-packages/django/template/base.py", line 883, in _resolve_lookup
    current = current[bit]
  File "/workspace/python/django_blog_venv/lib/python3.6/site-packages/django/utils/datastructures.py", line 85, in __getitem__
    raise MultiValueDictKeyError(repr(key))
django.utils.datastructures.MultiValueDictKeyError: "'year'"

During handling of the above exception, another exception occurred:

Traceback (most recent call last):
  File "/workspace/python/django_blog_venv/lib/python3.6/site-packages/django/template/base.py", line 891, in _resolve_lookup
    current = getattr(current, bit)
AttributeError: 'QueryDict' object has no attribute 'year'

During handling of the above exception, another exception occurred:

Traceback (most recent call last):
  File "/workspace/python/django_blog_venv/lib/python3.6/site-packages/django/template/base.py", line 898, in _resolve_lookup
    current = current[int(bit)]
ValueError: invalid literal for int() with base 10: 'year'

During handling of the above exception, another exception occurred:

Traceback (most recent call last):
  File "/workspace/python/django_blog_venv/lib/python3.6/site-packages/django/template/base.py", line 905, in _resolve_lookup
    (bit, current))  # missing attribute
django.template.base.VariableDoesNotExist: Failed lookup for key [year] in '<QueryDict: {}>'
2017-03-25 18:56:00,756 [Thread-4:123145393901568] [django.template:927] [base:_resolve_lookup] [DEBUG]- Exception while resolving variable 'month' in template 'index.html'.
Traceback (most recent call last):
  File "/workspace/python/django_blog_venv/lib/python3.6/site-packages/django/utils/datastructures.py", line 83, in __getitem__
    list_ = super(MultiValueDict, self).__getitem__(key)
KeyError: 'month'

During handling of the above exception, another exception occurred:

Traceback (most recent call last):
  File "/workspace/python/django_blog_venv/lib/python3.6/site-packages/django/template/base.py", line 883, in _resolve_lookup
    current = current[bit]
  File "/workspace/python/django_blog_venv/lib/python3.6/site-packages/django/utils/datastructures.py", line 85, in __getitem__
    raise MultiValueDictKeyError(repr(key))
django.utils.datastructures.MultiValueDictKeyError: "'month'"

During handling of the above exception, another exception occurred:

Traceback (most recent call last):
  File "/workspace/python/django_blog_venv/lib/python3.6/site-packages/django/template/base.py", line 891, in _resolve_lookup
    current = getattr(current, bit)
AttributeError: 'QueryDict' object has no attribute 'month'

During handling of the above exception, another exception occurred:

Traceback (most recent call last):
  File "/workspace/python/django_blog_venv/lib/python3.6/site-packages/django/template/base.py", line 898, in _resolve_lookup
    current = current[int(bit)]
ValueError: invalid literal for int() with base 10: 'month'

During handling of the above exception, another exception occurred:

Traceback (most recent call last):
  File "/workspace/python/django_blog_venv/lib/python3.6/site-packages/django/template/base.py", line 905, in _resolve_lookup
    (bit, current))  # missing attribute
django.template.base.VariableDoesNotExist: Failed lookup for key [month] in '<QueryDict: {}>'
2017-03-25 18:56:00,757 [Thread-4:123145393901568] [django.template:927] [base:_resolve_lookup] [DEBUG]- Exception while resolving variable 'cid' in template 'index.html'.
Traceback (most recent call last):
  File "/workspace/python/django_blog_venv/lib/python3.6/site-packages/django/utils/datastructures.py", line 83, in __getitem__
    list_ = super(MultiValueDict, self).__getitem__(key)
KeyError: 'cid'

During handling of the above exception, another exception occurred:

Traceback (most recent call last):
  File "/workspace/python/django_blog_venv/lib/python3.6/site-packages/django/template/base.py", line 883, in _resolve_lookup
    current = current[bit]
  File "/workspace/python/django_blog_venv/lib/python3.6/site-packages/django/utils/datastructures.py", line 85, in __getitem__
    raise MultiValueDictKeyError(repr(key))
django.utils.datastructures.MultiValueDictKeyError: "'cid'"

During handling of the above exception, another exception occurred:

Traceback (most recent call last):
  File "/workspace/python/django_blog_venv/lib/python3.6/site-packages/django/template/base.py", line 891, in _resolve_lookup
    current = getattr(current, bit)
AttributeError: 'QueryDict' object has no attribute 'cid'

During handling of the above exception, another exception occurred:

Traceback (most recent call last):
  File "/workspace/python/django_blog_venv/lib/python3.6/site-packages/django/template/base.py", line 898, in _resolve_lookup
    current = current[int(bit)]
ValueError: invalid literal for int() with base 10: 'cid'

During handling of the above exception, another exception occurred:

Traceback (most recent call last):
  File "/workspace/python/django_blog_venv/lib/python3.6/site-packages/django/template/base.py", line 905, in _resolve_lookup
    (bit, current))  # missing attribute
django.template.base.VariableDoesNotExist: Failed lookup for key [cid] in '<QueryDict: {}>'
2017-03-31 23:45:16,909 [Thread-2:123145488146432] [django.template:927] [base:_resolve_lookup] [DEBUG]- Exception while resolving variable 'year' in template 'index.html'.
Traceback (most recent call last):
  File "/Users/jiangzhuolin/workspace/python/environment/django_blog_venv/lib/python3.6/site-packages/django/utils/datastructures.py", line 83, in __getitem__
    list_ = super(MultiValueDict, self).__getitem__(key)
KeyError: 'year'

During handling of the above exception, another exception occurred:

Traceback (most recent call last):
  File "/Users/jiangzhuolin/workspace/python/environment/django_blog_venv/lib/python3.6/site-packages/django/template/base.py", line 883, in _resolve_lookup
    current = current[bit]
  File "/Users/jiangzhuolin/workspace/python/environment/django_blog_venv/lib/python3.6/site-packages/django/utils/datastructures.py", line 85, in __getitem__
    raise MultiValueDictKeyError(repr(key))
django.utils.datastructures.MultiValueDictKeyError: "'year'"

During handling of the above exception, another exception occurred:

Traceback (most recent call last):
  File "/Users/jiangzhuolin/workspace/python/environment/django_blog_venv/lib/python3.6/site-packages/django/template/base.py", line 891, in _resolve_lookup
    current = getattr(current, bit)
AttributeError: 'QueryDict' object has no attribute 'year'

During handling of the above exception, another exception occurred:

Traceback (most recent call last):
  File "/Users/jiangzhuolin/workspace/python/environment/django_blog_venv/lib/python3.6/site-packages/django/template/base.py", line 898, in _resolve_lookup
    current = current[int(bit)]
ValueError: invalid literal for int() with base 10: 'year'

During handling of the above exception, another exception occurred:

Traceback (most recent call last):
  File "/Users/jiangzhuolin/workspace/python/environment/django_blog_venv/lib/python3.6/site-packages/django/template/base.py", line 905, in _resolve_lookup
    (bit, current))  # missing attribute
django.template.base.VariableDoesNotExist: Failed lookup for key [year] in '<QueryDict: {}>'
2017-03-31 23:45:16,912 [Thread-2:123145488146432] [django.template:927] [base:_resolve_lookup] [DEBUG]- Exception while resolving variable 'month' in template 'index.html'.
Traceback (most recent call last):
  File "/Users/jiangzhuolin/workspace/python/environment/django_blog_venv/lib/python3.6/site-packages/django/utils/datastructures.py", line 83, in __getitem__
    list_ = super(MultiValueDict, self).__getitem__(key)
KeyError: 'month'

During handling of the above exception, another exception occurred:

Traceback (most recent call last):
  File "/Users/jiangzhuolin/workspace/python/environment/django_blog_venv/lib/python3.6/site-packages/django/template/base.py", line 883, in _resolve_lookup
    current = current[bit]
  File "/Users/jiangzhuolin/workspace/python/environment/django_blog_venv/lib/python3.6/site-packages/django/utils/datastructures.py", line 85, in __getitem__
    raise MultiValueDictKeyError(repr(key))
django.utils.datastructures.MultiValueDictKeyError: "'month'"

During handling of the above exception, another exception occurred:

Traceback (most recent call last):
  File "/Users/jiangzhuolin/workspace/python/environment/django_blog_venv/lib/python3.6/site-packages/django/template/base.py", line 891, in _resolve_lookup
    current = getattr(current, bit)
AttributeError: 'QueryDict' object has no attribute 'month'

During handling of the above exception, another exception occurred:

Traceback (most recent call last):
  File "/Users/jiangzhuolin/workspace/python/environment/django_blog_venv/lib/python3.6/site-packages/django/template/base.py", line 898, in _resolve_lookup
    current = current[int(bit)]
ValueError: invalid literal for int() with base 10: 'month'

During handling of the above exception, another exception occurred:

Traceback (most recent call last):
  File "/Users/jiangzhuolin/workspace/python/environment/django_blog_venv/lib/python3.6/site-packages/django/template/base.py", line 905, in _resolve_lookup
    (bit, current))  # missing attribute
django.template.base.VariableDoesNotExist: Failed lookup for key [month] in '<QueryDict: {}>'
2017-03-31 23:45:16,913 [Thread-2:123145488146432] [django.template:927] [base:_resolve_lookup] [DEBUG]- Exception while resolving variable 'cid' in template 'index.html'.
Traceback (most recent call last):
  File "/Users/jiangzhuolin/workspace/python/environment/django_blog_venv/lib/python3.6/site-packages/django/utils/datastructures.py", line 83, in __getitem__
    list_ = super(MultiValueDict, self).__getitem__(key)
KeyError: 'cid'

During handling of the above exception, another exception occurred:

Traceback (most recent call last):
  File "/Users/jiangzhuolin/workspace/python/environment/django_blog_venv/lib/python3.6/site-packages/django/template/base.py", line 883, in _resolve_lookup
    current = current[bit]
  File "/Users/jiangzhuolin/workspace/python/environment/django_blog_venv/lib/python3.6/site-packages/django/utils/datastructures.py", line 85, in __getitem__
    raise MultiValueDictKeyError(repr(key))
django.utils.datastructures.MultiValueDictKeyError: "'cid'"

During handling of the above exception, another exception occurred:

Traceback (most recent call last):
  File "/Users/jiangzhuolin/workspace/python/environment/django_blog_venv/lib/python3.6/site-packages/django/template/base.py", line 891, in _resolve_lookup
    current = getattr(current, bit)
AttributeError: 'QueryDict' object has no attribute 'cid'

During handling of the above exception, another exception occurred:

Traceback (most recent call last):
  File "/Users/jiangzhuolin/workspace/python/environment/django_blog_venv/lib/python3.6/site-packages/django/template/base.py", line 898, in _resolve_lookup
    current = current[int(bit)]
ValueError: invalid literal for int() with base 10: 'cid'

During handling of the above exception, another exception occurred:

Traceback (most recent call last):
  File "/Users/jiangzhuolin/workspace/python/environment/django_blog_venv/lib/python3.6/site-packages/django/template/base.py", line 905, in _resolve_lookup
    (bit, current))  # missing attribute
django.template.base.VariableDoesNotExist: Failed lookup for key [cid] in '<QueryDict: {}>'
2017-03-31 23:47:16,321 [Thread-19:123145488146432] [django.template:927] [base:_resolve_lookup] [DEBUG]- Exception while resolving variable 'year' in template 'index.html'.
Traceback (most recent call last):
  File "/Users/jiangzhuolin/workspace/python/environment/django_blog_venv/lib/python3.6/site-packages/django/utils/datastructures.py", line 83, in __getitem__
    list_ = super(MultiValueDict, self).__getitem__(key)
KeyError: 'year'

During handling of the above exception, another exception occurred:

Traceback (most recent call last):
  File "/Users/jiangzhuolin/workspace/python/environment/django_blog_venv/lib/python3.6/site-packages/django/template/base.py", line 883, in _resolve_lookup
    current = current[bit]
  File "/Users/jiangzhuolin/workspace/python/environment/django_blog_venv/lib/python3.6/site-packages/django/utils/datastructures.py", line 85, in __getitem__
    raise MultiValueDictKeyError(repr(key))
django.utils.datastructures.MultiValueDictKeyError: "'year'"

During handling of the above exception, another exception occurred:

Traceback (most recent call last):
  File "/Users/jiangzhuolin/workspace/python/environment/django_blog_venv/lib/python3.6/site-packages/django/template/base.py", line 891, in _resolve_lookup
    current = getattr(current, bit)
AttributeError: 'QueryDict' object has no attribute 'year'

During handling of the above exception, another exception occurred:

Traceback (most recent call last):
  File "/Users/jiangzhuolin/workspace/python/environment/django_blog_venv/lib/python3.6/site-packages/django/template/base.py", line 898, in _resolve_lookup
    current = current[int(bit)]
ValueError: invalid literal for int() with base 10: 'year'

During handling of the above exception, another exception occurred:

Traceback (most recent call last):
  File "/Users/jiangzhuolin/workspace/python/environment/django_blog_venv/lib/python3.6/site-packages/django/template/base.py", line 905, in _resolve_lookup
    (bit, current))  # missing attribute
django.template.base.VariableDoesNotExist: Failed lookup for key [year] in '<QueryDict: {}>'
2017-03-31 23:47:16,322 [Thread-19:123145488146432] [django.template:927] [base:_resolve_lookup] [DEBUG]- Exception while resolving variable 'month' in template 'index.html'.
Traceback (most recent call last):
  File "/Users/jiangzhuolin/workspace/python/environment/django_blog_venv/lib/python3.6/site-packages/django/utils/datastructures.py", line 83, in __getitem__
    list_ = super(MultiValueDict, self).__getitem__(key)
KeyError: 'month'

During handling of the above exception, another exception occurred:

Traceback (most recent call last):
  File "/Users/jiangzhuolin/workspace/python/environment/django_blog_venv/lib/python3.6/site-packages/django/template/base.py", line 883, in _resolve_lookup
    current = current[bit]
  File "/Users/jiangzhuolin/workspace/python/environment/django_blog_venv/lib/python3.6/site-packages/django/utils/datastructures.py", line 85, in __getitem__
    raise MultiValueDictKeyError(repr(key))
django.utils.datastructures.MultiValueDictKeyError: "'month'"

During handling of the above exception, another exception occurred:

Traceback (most recent call last):
  File "/Users/jiangzhuolin/workspace/python/environment/django_blog_venv/lib/python3.6/site-packages/django/template/base.py", line 891, in _resolve_lookup
    current = getattr(current, bit)
AttributeError: 'QueryDict' object has no attribute 'month'

During handling of the above exception, another exception occurred:

Traceback (most recent call last):
  File "/Users/jiangzhuolin/workspace/python/environment/django_blog_venv/lib/python3.6/site-packages/django/template/base.py", line 898, in _resolve_lookup
    current = current[int(bit)]
ValueError: invalid literal for int() with base 10: 'month'

During handling of the above exception, another exception occurred:

Traceback (most recent call last):
  File "/Users/jiangzhuolin/workspace/python/environment/django_blog_venv/lib/python3.6/site-packages/django/template/base.py", line 905, in _resolve_lookup
    (bit, current))  # missing attribute
django.template.base.VariableDoesNotExist: Failed lookup for key [month] in '<QueryDict: {}>'
2017-03-31 23:47:16,323 [Thread-19:123145488146432] [django.template:927] [base:_resolve_lookup] [DEBUG]- Exception while resolving variable 'cid' in template 'index.html'.
Traceback (most recent call last):
  File "/Users/jiangzhuolin/workspace/python/environment/django_blog_venv/lib/python3.6/site-packages/django/utils/datastructures.py", line 83, in __getitem__
    list_ = super(MultiValueDict, self).__getitem__(key)
KeyError: 'cid'

During handling of the above exception, another exception occurred:

Traceback (most recent call last):
  File "/Users/jiangzhuolin/workspace/python/environment/django_blog_venv/lib/python3.6/site-packages/django/template/base.py", line 883, in _resolve_lookup
    current = current[bit]
  File "/Users/jiangzhuolin/workspace/python/environment/django_blog_venv/lib/python3.6/site-packages/django/utils/datastructures.py", line 85, in __getitem__
    raise MultiValueDictKeyError(repr(key))
django.utils.datastructures.MultiValueDictKeyError: "'cid'"

During handling of the above exception, another exception occurred:

Traceback (most recent call last):
  File "/Users/jiangzhuolin/workspace/python/environment/django_blog_venv/lib/python3.6/site-packages/django/template/base.py", line 891, in _resolve_lookup
    current = getattr(current, bit)
AttributeError: 'QueryDict' object has no attribute 'cid'

During handling of the above exception, another exception occurred:

Traceback (most recent call last):
  File "/Users/jiangzhuolin/workspace/python/environment/django_blog_venv/lib/python3.6/site-packages/django/template/base.py", line 898, in _resolve_lookup
    current = current[int(bit)]
ValueError: invalid literal for int() with base 10: 'cid'

During handling of the above exception, another exception occurred:

Traceback (most recent call last):
  File "/Users/jiangzhuolin/workspace/python/environment/django_blog_venv/lib/python3.6/site-packages/django/template/base.py", line 905, in _resolve_lookup
    (bit, current))  # missing attribute
django.template.base.VariableDoesNotExist: Failed lookup for key [cid] in '<QueryDict: {}>'
2017-04-02 14:11:35,987 [Thread-2:123145541242880] [django.template:927] [base:_resolve_lookup] [DEBUG]- Exception while resolving variable 'year' in template 'index.html'.
Traceback (most recent call last):
  File "/Users/jiangzhuolin/workspace/python/environment/django_blog_venv/lib/python3.6/site-packages/django/utils/datastructures.py", line 83, in __getitem__
    list_ = super(MultiValueDict, self).__getitem__(key)
KeyError: 'year'

During handling of the above exception, another exception occurred:

Traceback (most recent call last):
  File "/Users/jiangzhuolin/workspace/python/environment/django_blog_venv/lib/python3.6/site-packages/django/template/base.py", line 883, in _resolve_lookup
    current = current[bit]
  File "/Users/jiangzhuolin/workspace/python/environment/django_blog_venv/lib/python3.6/site-packages/django/utils/datastructures.py", line 85, in __getitem__
    raise MultiValueDictKeyError(repr(key))
django.utils.datastructures.MultiValueDictKeyError: "'year'"

During handling of the above exception, another exception occurred:

Traceback (most recent call last):
  File "/Users/jiangzhuolin/workspace/python/environment/django_blog_venv/lib/python3.6/site-packages/django/template/base.py", line 891, in _resolve_lookup
    current = getattr(current, bit)
AttributeError: 'QueryDict' object has no attribute 'year'

During handling of the above exception, another exception occurred:

Traceback (most recent call last):
  File "/Users/jiangzhuolin/workspace/python/environment/django_blog_venv/lib/python3.6/site-packages/django/template/base.py", line 898, in _resolve_lookup
    current = current[int(bit)]
ValueError: invalid literal for int() with base 10: 'year'

During handling of the above exception, another exception occurred:

Traceback (most recent call last):
  File "/Users/jiangzhuolin/workspace/python/environment/django_blog_venv/lib/python3.6/site-packages/django/template/base.py", line 905, in _resolve_lookup
    (bit, current))  # missing attribute
django.template.base.VariableDoesNotExist: Failed lookup for key [year] in '<QueryDict: {}>'
2017-04-02 14:11:35,988 [Thread-2:123145541242880] [django.template:927] [base:_resolve_lookup] [DEBUG]- Exception while resolving variable 'month' in template 'index.html'.
Traceback (most recent call last):
  File "/Users/jiangzhuolin/workspace/python/environment/django_blog_venv/lib/python3.6/site-packages/django/utils/datastructures.py", line 83, in __getitem__
    list_ = super(MultiValueDict, self).__getitem__(key)
KeyError: 'month'

During handling of the above exception, another exception occurred:

Traceback (most recent call last):
  File "/Users/jiangzhuolin/workspace/python/environment/django_blog_venv/lib/python3.6/site-packages/django/template/base.py", line 883, in _resolve_lookup
    current = current[bit]
  File "/Users/jiangzhuolin/workspace/python/environment/django_blog_venv/lib/python3.6/site-packages/django/utils/datastructures.py", line 85, in __getitem__
    raise MultiValueDictKeyError(repr(key))
django.utils.datastructures.MultiValueDictKeyError: "'month'"

During handling of the above exception, another exception occurred:

Traceback (most recent call last):
  File "/Users/jiangzhuolin/workspace/python/environment/django_blog_venv/lib/python3.6/site-packages/django/template/base.py", line 891, in _resolve_lookup
    current = getattr(current, bit)
AttributeError: 'QueryDict' object has no attribute 'month'

During handling of the above exception, another exception occurred:

Traceback (most recent call last):
  File "/Users/jiangzhuolin/workspace/python/environment/django_blog_venv/lib/python3.6/site-packages/django/template/base.py", line 898, in _resolve_lookup
    current = current[int(bit)]
ValueError: invalid literal for int() with base 10: 'month'

During handling of the above exception, another exception occurred:

Traceback (most recent call last):
  File "/Users/jiangzhuolin/workspace/python/environment/django_blog_venv/lib/python3.6/site-packages/django/template/base.py", line 905, in _resolve_lookup
    (bit, current))  # missing attribute
django.template.base.VariableDoesNotExist: Failed lookup for key [month] in '<QueryDict: {}>'
2017-04-02 14:11:35,989 [Thread-2:123145541242880] [django.template:927] [base:_resolve_lookup] [DEBUG]- Exception while resolving variable 'cid' in template 'index.html'.
Traceback (most recent call last):
  File "/Users/jiangzhuolin/workspace/python/environment/django_blog_venv/lib/python3.6/site-packages/django/utils/datastructures.py", line 83, in __getitem__
    list_ = super(MultiValueDict, self).__getitem__(key)
KeyError: 'cid'

During handling of the above exception, another exception occurred:

Traceback (most recent call last):
  File "/Users/jiangzhuolin/workspace/python/environment/django_blog_venv/lib/python3.6/site-packages/django/template/base.py", line 883, in _resolve_lookup
    current = current[bit]
  File "/Users/jiangzhuolin/workspace/python/environment/django_blog_venv/lib/python3.6/site-packages/django/utils/datastructures.py", line 85, in __getitem__
    raise MultiValueDictKeyError(repr(key))
django.utils.datastructures.MultiValueDictKeyError: "'cid'"

During handling of the above exception, another exception occurred:

Traceback (most recent call last):
  File "/Users/jiangzhuolin/workspace/python/environment/django_blog_venv/lib/python3.6/site-packages/django/template/base.py", line 891, in _resolve_lookup
    current = getattr(current, bit)
AttributeError: 'QueryDict' object has no attribute 'cid'

During handling of the above exception, another exception occurred:

Traceback (most recent call last):
  File "/Users/jiangzhuolin/workspace/python/environment/django_blog_venv/lib/python3.6/site-packages/django/template/base.py", line 898, in _resolve_lookup
    current = current[int(bit)]
ValueError: invalid literal for int() with base 10: 'cid'

During handling of the above exception, another exception occurred:

Traceback (most recent call last):
  File "/Users/jiangzhuolin/workspace/python/environment/django_blog_venv/lib/python3.6/site-packages/django/template/base.py", line 905, in _resolve_lookup
    (bit, current))  # missing attribute
django.template.base.VariableDoesNotExist: Failed lookup for key [cid] in '<QueryDict: {}>'
2017-04-02 14:37:45,139 [Thread-21:123145541242880] [django.template:927] [base:_resolve_lookup] [DEBUG]- Exception while resolving variable 'year' in template 'index.html'.
Traceback (most recent call last):
  File "/Users/jiangzhuolin/workspace/python/environment/django_blog_venv/lib/python3.6/site-packages/django/utils/datastructures.py", line 83, in __getitem__
    list_ = super(MultiValueDict, self).__getitem__(key)
KeyError: 'year'

During handling of the above exception, another exception occurred:

Traceback (most recent call last):
  File "/Users/jiangzhuolin/workspace/python/environment/django_blog_venv/lib/python3.6/site-packages/django/template/base.py", line 883, in _resolve_lookup
    current = current[bit]
  File "/Users/jiangzhuolin/workspace/python/environment/django_blog_venv/lib/python3.6/site-packages/django/utils/datastructures.py", line 85, in __getitem__
    raise MultiValueDictKeyError(repr(key))
django.utils.datastructures.MultiValueDictKeyError: "'year'"

During handling of the above exception, another exception occurred:

Traceback (most recent call last):
  File "/Users/jiangzhuolin/workspace/python/environment/django_blog_venv/lib/python3.6/site-packages/django/template/base.py", line 891, in _resolve_lookup
    current = getattr(current, bit)
AttributeError: 'QueryDict' object has no attribute 'year'

During handling of the above exception, another exception occurred:

Traceback (most recent call last):
  File "/Users/jiangzhuolin/workspace/python/environment/django_blog_venv/lib/python3.6/site-packages/django/template/base.py", line 898, in _resolve_lookup
    current = current[int(bit)]
ValueError: invalid literal for int() with base 10: 'year'

During handling of the above exception, another exception occurred:

Traceback (most recent call last):
  File "/Users/jiangzhuolin/workspace/python/environment/django_blog_venv/lib/python3.6/site-packages/django/template/base.py", line 905, in _resolve_lookup
    (bit, current))  # missing attribute
django.template.base.VariableDoesNotExist: Failed lookup for key [year] in '<QueryDict: {}>'
2017-04-02 14:37:45,139 [Thread-21:123145541242880] [django.template:927] [base:_resolve_lookup] [DEBUG]- Exception while resolving variable 'month' in template 'index.html'.
Traceback (most recent call last):
  File "/Users/jiangzhuolin/workspace/python/environment/django_blog_venv/lib/python3.6/site-packages/django/utils/datastructures.py", line 83, in __getitem__
    list_ = super(MultiValueDict, self).__getitem__(key)
KeyError: 'month'

During handling of the above exception, another exception occurred:

Traceback (most recent call last):
  File "/Users/jiangzhuolin/workspace/python/environment/django_blog_venv/lib/python3.6/site-packages/django/template/base.py", line 883, in _resolve_lookup
    current = current[bit]
  File "/Users/jiangzhuolin/workspace/python/environment/django_blog_venv/lib/python3.6/site-packages/django/utils/datastructures.py", line 85, in __getitem__
    raise MultiValueDictKeyError(repr(key))
django.utils.datastructures.MultiValueDictKeyError: "'month'"

During handling of the above exception, another exception occurred:

Traceback (most recent call last):
  File "/Users/jiangzhuolin/workspace/python/environment/django_blog_venv/lib/python3.6/site-packages/django/template/base.py", line 891, in _resolve_lookup
    current = getattr(current, bit)
AttributeError: 'QueryDict' object has no attribute 'month'

During handling of the above exception, another exception occurred:

Traceback (most recent call last):
  File "/Users/jiangzhuolin/workspace/python/environment/django_blog_venv/lib/python3.6/site-packages/django/template/base.py", line 898, in _resolve_lookup
    current = current[int(bit)]
ValueError: invalid literal for int() with base 10: 'month'

During handling of the above exception, another exception occurred:

Traceback (most recent call last):
  File "/Users/jiangzhuolin/workspace/python/environment/django_blog_venv/lib/python3.6/site-packages/django/template/base.py", line 905, in _resolve_lookup
    (bit, current))  # missing attribute
django.template.base.VariableDoesNotExist: Failed lookup for key [month] in '<QueryDict: {}>'
2017-04-02 14:37:45,140 [Thread-21:123145541242880] [django.template:927] [base:_resolve_lookup] [DEBUG]- Exception while resolving variable 'cid' in template 'index.html'.
Traceback (most recent call last):
  File "/Users/jiangzhuolin/workspace/python/environment/django_blog_venv/lib/python3.6/site-packages/django/utils/datastructures.py", line 83, in __getitem__
    list_ = super(MultiValueDict, self).__getitem__(key)
KeyError: 'cid'

During handling of the above exception, another exception occurred:

Traceback (most recent call last):
  File "/Users/jiangzhuolin/workspace/python/environment/django_blog_venv/lib/python3.6/site-packages/django/template/base.py", line 883, in _resolve_lookup
    current = current[bit]
  File "/Users/jiangzhuolin/workspace/python/environment/django_blog_venv/lib/python3.6/site-packages/django/utils/datastructures.py", line 85, in __getitem__
    raise MultiValueDictKeyError(repr(key))
django.utils.datastructures.MultiValueDictKeyError: "'cid'"

During handling of the above exception, another exception occurred:

Traceback (most recent call last):
  File "/Users/jiangzhuolin/workspace/python/environment/django_blog_venv/lib/python3.6/site-packages/django/template/base.py", line 891, in _resolve_lookup
    current = getattr(current, bit)
AttributeError: 'QueryDict' object has no attribute 'cid'

During handling of the above exception, another exception occurred:

Traceback (most recent call last):
  File "/Users/jiangzhuolin/workspace/python/environment/django_blog_venv/lib/python3.6/site-packages/django/template/base.py", line 898, in _resolve_lookup
    current = current[int(bit)]
ValueError: invalid literal for int() with base 10: 'cid'

During handling of the above exception, another exception occurred:

Traceback (most recent call last):
  File "/Users/jiangzhuolin/workspace/python/environment/django_blog_venv/lib/python3.6/site-packages/django/template/base.py", line 905, in _resolve_lookup
    (bit, current))  # missing attribute
django.template.base.VariableDoesNotExist: Failed lookup for key [cid] in '<QueryDict: {}>'
2017-04-02 14:37:53,338 [Thread-32:123145541242880] [django.template:927] [base:_resolve_lookup] [DEBUG]- Exception while resolving variable 'year' in template 'index.html'.
Traceback (most recent call last):
  File "/Users/jiangzhuolin/workspace/python/environment/django_blog_venv/lib/python3.6/site-packages/django/utils/datastructures.py", line 83, in __getitem__
    list_ = super(MultiValueDict, self).__getitem__(key)
KeyError: 'year'

During handling of the above exception, another exception occurred:

Traceback (most recent call last):
  File "/Users/jiangzhuolin/workspace/python/environment/django_blog_venv/lib/python3.6/site-packages/django/template/base.py", line 883, in _resolve_lookup
    current = current[bit]
  File "/Users/jiangzhuolin/workspace/python/environment/django_blog_venv/lib/python3.6/site-packages/django/utils/datastructures.py", line 85, in __getitem__
    raise MultiValueDictKeyError(repr(key))
django.utils.datastructures.MultiValueDictKeyError: "'year'"

During handling of the above exception, another exception occurred:

Traceback (most recent call last):
  File "/Users/jiangzhuolin/workspace/python/environment/django_blog_venv/lib/python3.6/site-packages/django/template/base.py", line 891, in _resolve_lookup
    current = getattr(current, bit)
AttributeError: 'QueryDict' object has no attribute 'year'

During handling of the above exception, another exception occurred:

Traceback (most recent call last):
  File "/Users/jiangzhuolin/workspace/python/environment/django_blog_venv/lib/python3.6/site-packages/django/template/base.py", line 898, in _resolve_lookup
    current = current[int(bit)]
ValueError: invalid literal for int() with base 10: 'year'

During handling of the above exception, another exception occurred:

Traceback (most recent call last):
  File "/Users/jiangzhuolin/workspace/python/environment/django_blog_venv/lib/python3.6/site-packages/django/template/base.py", line 905, in _resolve_lookup
    (bit, current))  # missing attribute
django.template.base.VariableDoesNotExist: Failed lookup for key [year] in '<QueryDict: {}>'
2017-04-02 14:37:53,338 [Thread-32:123145541242880] [django.template:927] [base:_resolve_lookup] [DEBUG]- Exception while resolving variable 'month' in template 'index.html'.
Traceback (most recent call last):
  File "/Users/jiangzhuolin/workspace/python/environment/django_blog_venv/lib/python3.6/site-packages/django/utils/datastructures.py", line 83, in __getitem__
    list_ = super(MultiValueDict, self).__getitem__(key)
KeyError: 'month'

During handling of the above exception, another exception occurred:

Traceback (most recent call last):
  File "/Users/jiangzhuolin/workspace/python/environment/django_blog_venv/lib/python3.6/site-packages/django/template/base.py", line 883, in _resolve_lookup
    current = current[bit]
  File "/Users/jiangzhuolin/workspace/python/environment/django_blog_venv/lib/python3.6/site-packages/django/utils/datastructures.py", line 85, in __getitem__
    raise MultiValueDictKeyError(repr(key))
django.utils.datastructures.MultiValueDictKeyError: "'month'"

During handling of the above exception, another exception occurred:

Traceback (most recent call last):
  File "/Users/jiangzhuolin/workspace/python/environment/django_blog_venv/lib/python3.6/site-packages/django/template/base.py", line 891, in _resolve_lookup
    current = getattr(current, bit)
AttributeError: 'QueryDict' object has no attribute 'month'

During handling of the above exception, another exception occurred:

Traceback (most recent call last):
  File "/Users/jiangzhuolin/workspace/python/environment/django_blog_venv/lib/python3.6/site-packages/django/template/base.py", line 898, in _resolve_lookup
    current = current[int(bit)]
ValueError: invalid literal for int() with base 10: 'month'

During handling of the above exception, another exception occurred:

Traceback (most recent call last):
  File "/Users/jiangzhuolin/workspace/python/environment/django_blog_venv/lib/python3.6/site-packages/django/template/base.py", line 905, in _resolve_lookup
    (bit, current))  # missing attribute
django.template.base.VariableDoesNotExist: Failed lookup for key [month] in '<QueryDict: {}>'
2017-04-02 14:37:53,339 [Thread-32:123145541242880] [django.template:927] [base:_resolve_lookup] [DEBUG]- Exception while resolving variable 'cid' in template 'index.html'.
Traceback (most recent call last):
  File "/Users/jiangzhuolin/workspace/python/environment/django_blog_venv/lib/python3.6/site-packages/django/utils/datastructures.py", line 83, in __getitem__
    list_ = super(MultiValueDict, self).__getitem__(key)
KeyError: 'cid'

During handling of the above exception, another exception occurred:

Traceback (most recent call last):
  File "/Users/jiangzhuolin/workspace/python/environment/django_blog_venv/lib/python3.6/site-packages/django/template/base.py", line 883, in _resolve_lookup
    current = current[bit]
  File "/Users/jiangzhuolin/workspace/python/environment/django_blog_venv/lib/python3.6/site-packages/django/utils/datastructures.py", line 85, in __getitem__
    raise MultiValueDictKeyError(repr(key))
django.utils.datastructures.MultiValueDictKeyError: "'cid'"

During handling of the above exception, another exception occurred:

Traceback (most recent call last):
  File "/Users/jiangzhuolin/workspace/python/environment/django_blog_venv/lib/python3.6/site-packages/django/template/base.py", line 891, in _resolve_lookup
    current = getattr(current, bit)
AttributeError: 'QueryDict' object has no attribute 'cid'

During handling of the above exception, another exception occurred:

Traceback (most recent call last):
  File "/Users/jiangzhuolin/workspace/python/environment/django_blog_venv/lib/python3.6/site-packages/django/template/base.py", line 898, in _resolve_lookup
    current = current[int(bit)]
ValueError: invalid literal for int() with base 10: 'cid'

During handling of the above exception, another exception occurred:

Traceback (most recent call last):
  File "/Users/jiangzhuolin/workspace/python/environment/django_blog_venv/lib/python3.6/site-packages/django/template/base.py", line 905, in _resolve_lookup
    (bit, current))  # missing attribute
django.template.base.VariableDoesNotExist: Failed lookup for key [cid] in '<QueryDict: {}>'
2017-04-02 14:41:37,188 [Dummy-1:123145342717952] [django.db.backends:89] [utils:execute] [DEBUG]- (0.000) SET SQL_AUTO_IS_NULL = 0; args=None
2017-04-02 14:41:37,268 [Dummy-1:123145342717952] [django.db.backends:89] [utils:execute] [DEBUG]- (0.000) SET SQL_AUTO_IS_NULL = 0; args=None
2017-04-02 14:41:37,270 [Dummy-1:123145342717952] [django.db.backends:89] [utils:execute] [DEBUG]- (0.001) SHOW FULL TABLES; args=None
2017-04-02 14:41:37,274 [Dummy-1:123145342717952] [django.db.backends:89] [utils:execute] [DEBUG]- (0.001) SELECT `django_migrations`.`app`, `django_migrations`.`name` FROM `django_migrations`; args=()
2017-04-02 14:41:37,802 [Thread-2:123145347973120] [django.db.backends:89] [utils:execute] [DEBUG]- (0.000) SET SQL_AUTO_IS_NULL = 0; args=None
2017-04-02 14:41:37,802 [Thread-2:123145347973120] [django.db.backends:89] [utils:execute] [DEBUG]- (0.000) SELECT COUNT(*) AS `__count` FROM `blog_article`; args=()
2017-04-02 14:41:37,804 [Thread-2:123145347973120] [django.db.backends:89] [utils:execute] [DEBUG]- (0.001) SELECT `blog_article`.`date_publish` FROM `blog_article` ORDER BY `blog_article`.`date_publish` DESC; args=()
2017-04-02 14:41:37,809 [Thread-2:123145347973120] [django.db.backends:89] [utils:execute] [DEBUG]- (0.001) SELECT `blog_article`.`date_publish` FROM `blog_article` ORDER BY `blog_article`.`date_publish` DESC; args=()
2017-04-02 14:41:37,811 [Thread-2:123145347973120] [django.db.backends:89] [utils:execute] [DEBUG]- (0.001) SELECT `blog_comment`.`article_id`, COUNT(`blog_comment`.`article_id`) AS `comment_count` FROM `blog_comment` GROUP BY `blog_comment`.`article_id` ORDER BY `comment_count` DESC LIMIT 6; args=()
2017-04-02 14:41:37,818 [Thread-2:123145347973120] [django.db.backends:89] [utils:execute] [DEBUG]- (0.004) SELECT `blog_article`.`id`, `blog_article`.`title`, `blog_article`.`desc`, `blog_article`.`content`, `blog_article`.`click_count`, `blog_article`.`is_recommend`, `blog_article`.`date_publish`, `blog_article`.`user_id`, `blog_article`.`category_id` FROM `blog_article` WHERE `blog_article`.`id` = 7; args=(7,)
2017-04-02 14:41:37,822 [Thread-2:123145347973120] [django.db.backends:89] [utils:execute] [DEBUG]- (0.003) SELECT `blog_article`.`id`, `blog_article`.`title`, `blog_article`.`desc`, `blog_article`.`content`, `blog_article`.`click_count`, `blog_article`.`is_recommend`, `blog_article`.`date_publish`, `blog_article`.`user_id`, `blog_article`.`category_id` FROM `blog_article` WHERE `blog_article`.`id` = 3; args=(3,)
2017-04-02 14:41:37,824 [Thread-2:123145347973120] [django.db.backends:89] [utils:execute] [DEBUG]- (0.001) SELECT `blog_article`.`id`, `blog_article`.`title`, `blog_article`.`desc`, `blog_article`.`content`, `blog_article`.`click_count`, `blog_article`.`is_recommend`, `blog_article`.`date_publish`, `blog_article`.`user_id`, `blog_article`.`category_id` FROM `blog_article` WHERE `blog_article`.`id` = 5; args=(5,)
2017-04-02 14:41:37,838 [Thread-2:123145347973120] [django.db.backends:89] [utils:execute] [DEBUG]- (0.007) SELECT `blog_category`.`id`, `blog_category`.`name`, `blog_category`.`index` FROM `blog_category` ORDER BY `blog_category`.`index` DESC, `blog_category`.`id` ASC; args=()
2017-04-02 14:41:37,855 [Thread-2:123145347973120] [django.db.backends:89] [utils:execute] [DEBUG]- (0.010) SELECT `blog_article`.`id`, `blog_article`.`title`, `blog_article`.`desc`, `blog_article`.`content`, `blog_article`.`click_count`, `blog_article`.`is_recommend`, `blog_article`.`date_publish`, `blog_article`.`user_id`, `blog_article`.`category_id` FROM `blog_article` ORDER BY `blog_article`.`date_publish` DESC LIMIT 5; args=()
2017-04-02 14:41:37,860 [Thread-2:123145347973120] [django.db.backends:89] [utils:execute] [DEBUG]- (0.003) SELECT `blog_tag`.`id`, `blog_tag`.`name` FROM `blog_tag` INNER JOIN `blog_article_tag` ON (`blog_tag`.`id` = `blog_article_tag`.`tag_id`) WHERE `blog_article_tag`.`article_id` = 7 ORDER BY `blog_tag`.`id` ASC; args=(7,)
2017-04-02 14:41:37,865 [Thread-2:123145347973120] [django.db.backends:89] [utils:execute] [DEBUG]- (0.001) SELECT COUNT(*) AS `__count` FROM `blog_comment` WHERE `blog_comment`.`article_id` = 7; args=(7,)
2017-04-02 14:41:37,867 [Thread-2:123145347973120] [django.db.backends:89] [utils:execute] [DEBUG]- (0.001) SELECT `blog_tag`.`id`, `blog_tag`.`name` FROM `blog_tag` INNER JOIN `blog_article_tag` ON (`blog_tag`.`id` = `blog_article_tag`.`tag_id`) WHERE `blog_article_tag`.`article_id` = 6 ORDER BY `blog_tag`.`id` ASC; args=(6,)
2017-04-02 14:41:37,869 [Thread-2:123145347973120] [django.db.backends:89] [utils:execute] [DEBUG]- (0.001) SELECT COUNT(*) AS `__count` FROM `blog_comment` WHERE `blog_comment`.`article_id` = 6; args=(6,)
2017-04-02 14:41:37,872 [Thread-2:123145347973120] [django.db.backends:89] [utils:execute] [DEBUG]- (0.001) SELECT `blog_tag`.`id`, `blog_tag`.`name` FROM `blog_tag` INNER JOIN `blog_article_tag` ON (`blog_tag`.`id` = `blog_article_tag`.`tag_id`) WHERE `blog_article_tag`.`article_id` = 5 ORDER BY `blog_tag`.`id` ASC; args=(5,)
2017-04-02 14:41:37,873 [Thread-2:123145347973120] [django.db.backends:89] [utils:execute] [DEBUG]- (0.001) SELECT COUNT(*) AS `__count` FROM `blog_comment` WHERE `blog_comment`.`article_id` = 5; args=(5,)
2017-04-02 14:41:37,876 [Thread-2:123145347973120] [django.db.backends:89] [utils:execute] [DEBUG]- (0.001) SELECT `blog_tag`.`id`, `blog_tag`.`name` FROM `blog_tag` INNER JOIN `blog_article_tag` ON (`blog_tag`.`id` = `blog_article_tag`.`tag_id`) WHERE `blog_article_tag`.`article_id` = 4 ORDER BY `blog_tag`.`id` ASC; args=(4,)
2017-04-02 14:41:37,880 [Thread-2:123145347973120] [django.db.backends:89] [utils:execute] [DEBUG]- (0.001) SELECT COUNT(*) AS `__count` FROM `blog_comment` WHERE `blog_comment`.`article_id` = 4; args=(4,)
2017-04-02 14:41:37,882 [Thread-2:123145347973120] [django.db.backends:89] [utils:execute] [DEBUG]- (0.001) SELECT `blog_tag`.`id`, `blog_tag`.`name` FROM `blog_tag` INNER JOIN `blog_article_tag` ON (`blog_tag`.`id` = `blog_article_tag`.`tag_id`) WHERE `blog_article_tag`.`article_id` = 3 ORDER BY `blog_tag`.`id` ASC; args=(3,)
2017-04-02 14:41:37,884 [Thread-2:123145347973120] [django.db.backends:89] [utils:execute] [DEBUG]- (0.000) SELECT COUNT(*) AS `__count` FROM `blog_comment` WHERE `blog_comment`.`article_id` = 3; args=(3,)
2017-04-02 14:41:37,887 [Thread-2:123145347973120] [django.template:927] [base:_resolve_lookup] [DEBUG]- Exception while resolving variable 'year' in template 'index.html'.
Traceback (most recent call last):
  File "/Users/jiangzhuolin/workspace/python/environment/django_blog_venv/lib/python3.6/site-packages/django/utils/datastructures.py", line 83, in __getitem__
    list_ = super(MultiValueDict, self).__getitem__(key)
KeyError: 'year'

During handling of the above exception, another exception occurred:

Traceback (most recent call last):
  File "/Users/jiangzhuolin/workspace/python/environment/django_blog_venv/lib/python3.6/site-packages/django/template/base.py", line 883, in _resolve_lookup
    current = current[bit]
  File "/Users/jiangzhuolin/workspace/python/environment/django_blog_venv/lib/python3.6/site-packages/django/utils/datastructures.py", line 85, in __getitem__
    raise MultiValueDictKeyError(repr(key))
django.utils.datastructures.MultiValueDictKeyError: "'year'"

During handling of the above exception, another exception occurred:

Traceback (most recent call last):
  File "/Users/jiangzhuolin/workspace/python/environment/django_blog_venv/lib/python3.6/site-packages/django/template/base.py", line 891, in _resolve_lookup
    current = getattr(current, bit)
AttributeError: 'QueryDict' object has no attribute 'year'

During handling of the above exception, another exception occurred:

Traceback (most recent call last):
  File "/Users/jiangzhuolin/workspace/python/environment/django_blog_venv/lib/python3.6/site-packages/django/template/base.py", line 898, in _resolve_lookup
    current = current[int(bit)]
ValueError: invalid literal for int() with base 10: 'year'

During handling of the above exception, another exception occurred:

Traceback (most recent call last):
  File "/Users/jiangzhuolin/workspace/python/environment/django_blog_venv/lib/python3.6/site-packages/django/template/base.py", line 905, in _resolve_lookup
    (bit, current))  # missing attribute
django.template.base.VariableDoesNotExist: Failed lookup for key [year] in '<QueryDict: {}>'
2017-04-02 14:41:37,888 [Thread-2:123145347973120] [django.template:927] [base:_resolve_lookup] [DEBUG]- Exception while resolving variable 'month' in template 'index.html'.
Traceback (most recent call last):
  File "/Users/jiangzhuolin/workspace/python/environment/django_blog_venv/lib/python3.6/site-packages/django/utils/datastructures.py", line 83, in __getitem__
    list_ = super(MultiValueDict, self).__getitem__(key)
KeyError: 'month'

During handling of the above exception, another exception occurred:

Traceback (most recent call last):
  File "/Users/jiangzhuolin/workspace/python/environment/django_blog_venv/lib/python3.6/site-packages/django/template/base.py", line 883, in _resolve_lookup
    current = current[bit]
  File "/Users/jiangzhuolin/workspace/python/environment/django_blog_venv/lib/python3.6/site-packages/django/utils/datastructures.py", line 85, in __getitem__
    raise MultiValueDictKeyError(repr(key))
django.utils.datastructures.MultiValueDictKeyError: "'month'"

During handling of the above exception, another exception occurred:

Traceback (most recent call last):
  File "/Users/jiangzhuolin/workspace/python/environment/django_blog_venv/lib/python3.6/site-packages/django/template/base.py", line 891, in _resolve_lookup
    current = getattr(current, bit)
AttributeError: 'QueryDict' object has no attribute 'month'

During handling of the above exception, another exception occurred:

Traceback (most recent call last):
  File "/Users/jiangzhuolin/workspace/python/environment/django_blog_venv/lib/python3.6/site-packages/django/template/base.py", line 898, in _resolve_lookup
    current = current[int(bit)]
ValueError: invalid literal for int() with base 10: 'month'

During handling of the above exception, another exception occurred:

Traceback (most recent call last):
  File "/Users/jiangzhuolin/workspace/python/environment/django_blog_venv/lib/python3.6/site-packages/django/template/base.py", line 905, in _resolve_lookup
    (bit, current))  # missing attribute
django.template.base.VariableDoesNotExist: Failed lookup for key [month] in '<QueryDict: {}>'
2017-04-02 14:41:37,889 [Thread-2:123145347973120] [django.template:927] [base:_resolve_lookup] [DEBUG]- Exception while resolving variable 'cid' in template 'index.html'.
Traceback (most recent call last):
  File "/Users/jiangzhuolin/workspace/python/environment/django_blog_venv/lib/python3.6/site-packages/django/utils/datastructures.py", line 83, in __getitem__
    list_ = super(MultiValueDict, self).__getitem__(key)
KeyError: 'cid'

During handling of the above exception, another exception occurred:

Traceback (most recent call last):
  File "/Users/jiangzhuolin/workspace/python/environment/django_blog_venv/lib/python3.6/site-packages/django/template/base.py", line 883, in _resolve_lookup
    current = current[bit]
  File "/Users/jiangzhuolin/workspace/python/environment/django_blog_venv/lib/python3.6/site-packages/django/utils/datastructures.py", line 85, in __getitem__
    raise MultiValueDictKeyError(repr(key))
django.utils.datastructures.MultiValueDictKeyError: "'cid'"

During handling of the above exception, another exception occurred:

Traceback (most recent call last):
  File "/Users/jiangzhuolin/workspace/python/environment/django_blog_venv/lib/python3.6/site-packages/django/template/base.py", line 891, in _resolve_lookup
    current = getattr(current, bit)
AttributeError: 'QueryDict' object has no attribute 'cid'

During handling of the above exception, another exception occurred:

Traceback (most recent call last):
  File "/Users/jiangzhuolin/workspace/python/environment/django_blog_venv/lib/python3.6/site-packages/django/template/base.py", line 898, in _resolve_lookup
    current = current[int(bit)]
ValueError: invalid literal for int() with base 10: 'cid'

During handling of the above exception, another exception occurred:

Traceback (most recent call last):
  File "/Users/jiangzhuolin/workspace/python/environment/django_blog_venv/lib/python3.6/site-packages/django/template/base.py", line 905, in _resolve_lookup
    (bit, current))  # missing attribute
django.template.base.VariableDoesNotExist: Failed lookup for key [cid] in '<QueryDict: {}>'
2017-04-02 14:41:37,891 [Thread-2:123145347973120] [django.db.backends:89] [utils:execute] [DEBUG]- (0.001) SELECT `blog_article`.`id`, `blog_article`.`title`, `blog_article`.`desc`, `blog_article`.`content`, `blog_article`.`click_count`, `blog_article`.`is_recommend`, `blog_article`.`date_publish`, `blog_article`.`user_id`, `blog_article`.`category_id` FROM `blog_article` ORDER BY `blog_article`.`click_count` DESC LIMIT 6; args=()
2017-04-02 14:41:37,896 [Thread-2:123145347973120] [django.db.backends:89] [utils:execute] [DEBUG]- (0.001) SELECT `blog_article`.`id`, `blog_article`.`title`, `blog_article`.`desc`, `blog_article`.`content`, `blog_article`.`click_count`, `blog_article`.`is_recommend`, `blog_article`.`date_publish`, `blog_article`.`user_id`, `blog_article`.`category_id` FROM `blog_article` WHERE `blog_article`.`is_recommend` = 1 ORDER BY `blog_article`.`date_publish` DESC LIMIT 6; args=(True,)
2017-04-02 14:41:37,898 [Thread-2:123145347973120] [django.db.backends:89] [utils:execute] [DEBUG]- (0.001) SELECT `blog_tag`.`id`, `blog_tag`.`name` FROM `blog_tag` ORDER BY `blog_tag`.`id` ASC; args=()
2017-04-02 14:41:39,036 [Thread-25:123145347973120] [django.template:927] [base:_resolve_lookup] [DEBUG]- Exception while resolving variable 'name' in template 'unknown'.
Traceback (most recent call last):
  File "/Users/jiangzhuolin/workspace/python/environment/django_blog_venv/lib/python3.6/site-packages/django/core/handlers/base.py", line 134, in get_response
    resolver_match = resolver.resolve(request.path_info)
  File "/Users/jiangzhuolin/workspace/python/environment/django_blog_venv/lib/python3.6/site-packages/django/core/urlresolvers.py", line 404, in resolve
    raise Resolver404({'tried': tried, 'path': new_path})
django.core.urlresolvers.Resolver404: {'tried': [[<RegexURLResolver <RegexURLPattern list> (admin:admin) ^admin/>], [<RegexURLPattern None ^uploads/(?P<path>.*)$>], [<RegexURLPattern upload_image ^admin/upload/(?P<dir_name>[^/]+)$>], [<RegexURLResolver <module 'blog.urls' from '/Users/jiangzhuolin/workspace/python/projects/my_blog/blog/urls.py'> (None:None) ^>, <RegexURLPattern index ^index/>], [<RegexURLResolver <module 'blog.urls' from '/Users/jiangzhuolin/workspace/python/projects/my_blog/blog/urls.py'> (None:None) ^>, <RegexURLPattern index ^$>], [<RegexURLResolver <module 'blog.urls' from '/Users/jiangzhuolin/workspace/python/projects/my_blog/blog/urls.py'> (None:None) ^>, <RegexURLPattern archive ^archive/$>], [<RegexURLResolver <module 'blog.urls' from '/Users/jiangzhuolin/workspace/python/projects/my_blog/blog/urls.py'> (None:None) ^>, <RegexURLPattern article ^article/$>], [<RegexURLResolver <module 'blog.urls' from '/Users/jiangzhuolin/workspace/python/projects/my_blog/blog/urls.py'> (None:None) ^>, <RegexURLPattern login ^login/$>], [<RegexURLResolver <module 'blog.urls' from '/Users/jiangzhuolin/workspace/python/projects/my_blog/blog/urls.py'> (None:None) ^>, <RegexURLPattern reg ^reg/$>], [<RegexURLResolver <module 'blog.urls' from '/Users/jiangzhuolin/workspace/python/projects/my_blog/blog/urls.py'> (None:None) ^>, <RegexURLPattern logout ^logout/$>], [<RegexURLResolver <module 'blog.urls' from '/Users/jiangzhuolin/workspace/python/projects/my_blog/blog/urls.py'> (None:None) ^>, <RegexURLPattern comment_post ^comment_post$>], [<RegexURLResolver <module 'blog.urls' from '/Users/jiangzhuolin/workspace/python/projects/my_blog/blog/urls.py'> (None:None) ^>, <RegexURLPattern category ^category>], [<RegexURLResolver <module 'blog.urls' from '/Users/jiangzhuolin/workspace/python/projects/my_blog/blog/urls.py'> (None:None) ^>, <RegexURLPattern test ^test>]], 'path': 'favicon.ico'}

During handling of the above exception, another exception occurred:

Traceback (most recent call last):
  File "/Users/jiangzhuolin/workspace/python/environment/django_blog_venv/lib/python3.6/site-packages/django/template/base.py", line 883, in _resolve_lookup
    current = current[bit]
TypeError: 'RegexURLResolver' object is not subscriptable

During handling of the above exception, another exception occurred:

Traceback (most recent call last):
  File "/Users/jiangzhuolin/workspace/python/environment/django_blog_venv/lib/python3.6/site-packages/django/template/base.py", line 891, in _resolve_lookup
    current = getattr(current, bit)
AttributeError: 'RegexURLResolver' object has no attribute 'name'

During handling of the above exception, another exception occurred:

Traceback (most recent call last):
  File "/Users/jiangzhuolin/workspace/python/environment/django_blog_venv/lib/python3.6/site-packages/django/template/base.py", line 898, in _resolve_lookup
    current = current[int(bit)]
ValueError: invalid literal for int() with base 10: 'name'

During handling of the above exception, another exception occurred:

Traceback (most recent call last):
  File "/Users/jiangzhuolin/workspace/python/environment/django_blog_venv/lib/python3.6/site-packages/django/template/base.py", line 905, in _resolve_lookup
    (bit, current))  # missing attribute
django.template.base.VariableDoesNotExist: Failed lookup for key [name] in '<RegexURLResolver <RegexURLPattern list> (admin:admin) ^admin/>'
2017-04-02 14:42:21,562 [Thread-2:123145361154048] [django.template:927] [base:_resolve_lookup] [DEBUG]- Exception while resolving variable 'year' in template 'index.html'.
Traceback (most recent call last):
  File "/Users/jiangzhuolin/workspace/python/environment/django_blog_venv/lib/python3.6/site-packages/django/utils/datastructures.py", line 83, in __getitem__
    list_ = super(MultiValueDict, self).__getitem__(key)
KeyError: 'year'

During handling of the above exception, another exception occurred:

Traceback (most recent call last):
  File "/Users/jiangzhuolin/workspace/python/environment/django_blog_venv/lib/python3.6/site-packages/django/template/base.py", line 883, in _resolve_lookup
    current = current[bit]
  File "/Users/jiangzhuolin/workspace/python/environment/django_blog_venv/lib/python3.6/site-packages/django/utils/datastructures.py", line 85, in __getitem__
    raise MultiValueDictKeyError(repr(key))
django.utils.datastructures.MultiValueDictKeyError: "'year'"

During handling of the above exception, another exception occurred:

Traceback (most recent call last):
  File "/Users/jiangzhuolin/workspace/python/environment/django_blog_venv/lib/python3.6/site-packages/django/template/base.py", line 891, in _resolve_lookup
    current = getattr(current, bit)
AttributeError: 'QueryDict' object has no attribute 'year'

During handling of the above exception, another exception occurred:

Traceback (most recent call last):
  File "/Users/jiangzhuolin/workspace/python/environment/django_blog_venv/lib/python3.6/site-packages/django/template/base.py", line 898, in _resolve_lookup
    current = current[int(bit)]
ValueError: invalid literal for int() with base 10: 'year'

During handling of the above exception, another exception occurred:

Traceback (most recent call last):
  File "/Users/jiangzhuolin/workspace/python/environment/django_blog_venv/lib/python3.6/site-packages/django/template/base.py", line 905, in _resolve_lookup
    (bit, current))  # missing attribute
django.template.base.VariableDoesNotExist: Failed lookup for key [year] in '<QueryDict: {}>'
2017-04-02 14:42:21,563 [Thread-2:123145361154048] [django.template:927] [base:_resolve_lookup] [DEBUG]- Exception while resolving variable 'month' in template 'index.html'.
Traceback (most recent call last):
  File "/Users/jiangzhuolin/workspace/python/environment/django_blog_venv/lib/python3.6/site-packages/django/utils/datastructures.py", line 83, in __getitem__
    list_ = super(MultiValueDict, self).__getitem__(key)
KeyError: 'month'

During handling of the above exception, another exception occurred:

Traceback (most recent call last):
  File "/Users/jiangzhuolin/workspace/python/environment/django_blog_venv/lib/python3.6/site-packages/django/template/base.py", line 883, in _resolve_lookup
    current = current[bit]
  File "/Users/jiangzhuolin/workspace/python/environment/django_blog_venv/lib/python3.6/site-packages/django/utils/datastructures.py", line 85, in __getitem__
    raise MultiValueDictKeyError(repr(key))
django.utils.datastructures.MultiValueDictKeyError: "'month'"

During handling of the above exception, another exception occurred:

Traceback (most recent call last):
  File "/Users/jiangzhuolin/workspace/python/environment/django_blog_venv/lib/python3.6/site-packages/django/template/base.py", line 891, in _resolve_lookup
    current = getattr(current, bit)
AttributeError: 'QueryDict' object has no attribute 'month'

During handling of the above exception, another exception occurred:

Traceback (most recent call last):
  File "/Users/jiangzhuolin/workspace/python/environment/django_blog_venv/lib/python3.6/site-packages/django/template/base.py", line 898, in _resolve_lookup
    current = current[int(bit)]
ValueError: invalid literal for int() with base 10: 'month'

During handling of the above exception, another exception occurred:

Traceback (most recent call last):
  File "/Users/jiangzhuolin/workspace/python/environment/django_blog_venv/lib/python3.6/site-packages/django/template/base.py", line 905, in _resolve_lookup
    (bit, current))  # missing attribute
django.template.base.VariableDoesNotExist: Failed lookup for key [month] in '<QueryDict: {}>'
2017-04-02 14:42:21,564 [Thread-2:123145361154048] [django.template:927] [base:_resolve_lookup] [DEBUG]- Exception while resolving variable 'cid' in template 'index.html'.
Traceback (most recent call last):
  File "/Users/jiangzhuolin/workspace/python/environment/django_blog_venv/lib/python3.6/site-packages/django/utils/datastructures.py", line 83, in __getitem__
    list_ = super(MultiValueDict, self).__getitem__(key)
KeyError: 'cid'

During handling of the above exception, another exception occurred:

Traceback (most recent call last):
  File "/Users/jiangzhuolin/workspace/python/environment/django_blog_venv/lib/python3.6/site-packages/django/template/base.py", line 883, in _resolve_lookup
    current = current[bit]
  File "/Users/jiangzhuolin/workspace/python/environment/django_blog_venv/lib/python3.6/site-packages/django/utils/datastructures.py", line 85, in __getitem__
    raise MultiValueDictKeyError(repr(key))
django.utils.datastructures.MultiValueDictKeyError: "'cid'"

During handling of the above exception, another exception occurred:

Traceback (most recent call last):
  File "/Users/jiangzhuolin/workspace/python/environment/django_blog_venv/lib/python3.6/site-packages/django/template/base.py", line 891, in _resolve_lookup
    current = getattr(current, bit)
AttributeError: 'QueryDict' object has no attribute 'cid'

During handling of the above exception, another exception occurred:

Traceback (most recent call last):
  File "/Users/jiangzhuolin/workspace/python/environment/django_blog_venv/lib/python3.6/site-packages/django/template/base.py", line 898, in _resolve_lookup
    current = current[int(bit)]
ValueError: invalid literal for int() with base 10: 'cid'

During handling of the above exception, another exception occurred:

Traceback (most recent call last):
  File "/Users/jiangzhuolin/workspace/python/environment/django_blog_venv/lib/python3.6/site-packages/django/template/base.py", line 905, in _resolve_lookup
    (bit, current))  # missing attribute
django.template.base.VariableDoesNotExist: Failed lookup for key [cid] in '<QueryDict: {}>'
2017-04-02 14:51:12,309 [Thread-11:123145361154048] [django.template:927] [base:_resolve_lookup] [DEBUG]- Exception while resolving variable 'year' in template 'index.html'.
Traceback (most recent call last):
  File "/Users/jiangzhuolin/workspace/python/environment/django_blog_venv/lib/python3.6/site-packages/django/utils/datastructures.py", line 83, in __getitem__
    list_ = super(MultiValueDict, self).__getitem__(key)
KeyError: 'year'

During handling of the above exception, another exception occurred:

Traceback (most recent call last):
  File "/Users/jiangzhuolin/workspace/python/environment/django_blog_venv/lib/python3.6/site-packages/django/template/base.py", line 883, in _resolve_lookup
    current = current[bit]
  File "/Users/jiangzhuolin/workspace/python/environment/django_blog_venv/lib/python3.6/site-packages/django/utils/datastructures.py", line 85, in __getitem__
    raise MultiValueDictKeyError(repr(key))
django.utils.datastructures.MultiValueDictKeyError: "'year'"

During handling of the above exception, another exception occurred:

Traceback (most recent call last):
  File "/Users/jiangzhuolin/workspace/python/environment/django_blog_venv/lib/python3.6/site-packages/django/template/base.py", line 891, in _resolve_lookup
    current = getattr(current, bit)
AttributeError: 'QueryDict' object has no attribute 'year'

During handling of the above exception, another exception occurred:

Traceback (most recent call last):
  File "/Users/jiangzhuolin/workspace/python/environment/django_blog_venv/lib/python3.6/site-packages/django/template/base.py", line 898, in _resolve_lookup
    current = current[int(bit)]
ValueError: invalid literal for int() with base 10: 'year'

During handling of the above exception, another exception occurred:

Traceback (most recent call last):
  File "/Users/jiangzhuolin/workspace/python/environment/django_blog_venv/lib/python3.6/site-packages/django/template/base.py", line 905, in _resolve_lookup
    (bit, current))  # missing attribute
django.template.base.VariableDoesNotExist: Failed lookup for key [year] in '<QueryDict: {}>'
2017-04-02 14:51:12,309 [Thread-11:123145361154048] [django.template:927] [base:_resolve_lookup] [DEBUG]- Exception while resolving variable 'month' in template 'index.html'.
Traceback (most recent call last):
  File "/Users/jiangzhuolin/workspace/python/environment/django_blog_venv/lib/python3.6/site-packages/django/utils/datastructures.py", line 83, in __getitem__
    list_ = super(MultiValueDict, self).__getitem__(key)
KeyError: 'month'

During handling of the above exception, another exception occurred:

Traceback (most recent call last):
  File "/Users/jiangzhuolin/workspace/python/environment/django_blog_venv/lib/python3.6/site-packages/django/template/base.py", line 883, in _resolve_lookup
    current = current[bit]
  File "/Users/jiangzhuolin/workspace/python/environment/django_blog_venv/lib/python3.6/site-packages/django/utils/datastructures.py", line 85, in __getitem__
    raise MultiValueDictKeyError(repr(key))
django.utils.datastructures.MultiValueDictKeyError: "'month'"

During handling of the above exception, another exception occurred:

Traceback (most recent call last):
  File "/Users/jiangzhuolin/workspace/python/environment/django_blog_venv/lib/python3.6/site-packages/django/template/base.py", line 891, in _resolve_lookup
    current = getattr(current, bit)
AttributeError: 'QueryDict' object has no attribute 'month'

During handling of the above exception, another exception occurred:

Traceback (most recent call last):
  File "/Users/jiangzhuolin/workspace/python/environment/django_blog_venv/lib/python3.6/site-packages/django/template/base.py", line 898, in _resolve_lookup
    current = current[int(bit)]
ValueError: invalid literal for int() with base 10: 'month'

During handling of the above exception, another exception occurred:

Traceback (most recent call last):
  File "/Users/jiangzhuolin/workspace/python/environment/django_blog_venv/lib/python3.6/site-packages/django/template/base.py", line 905, in _resolve_lookup
    (bit, current))  # missing attribute
django.template.base.VariableDoesNotExist: Failed lookup for key [month] in '<QueryDict: {}>'
2017-04-02 14:51:12,310 [Thread-11:123145361154048] [django.template:927] [base:_resolve_lookup] [DEBUG]- Exception while resolving variable 'cid' in template 'index.html'.
Traceback (most recent call last):
  File "/Users/jiangzhuolin/workspace/python/environment/django_blog_venv/lib/python3.6/site-packages/django/utils/datastructures.py", line 83, in __getitem__
    list_ = super(MultiValueDict, self).__getitem__(key)
KeyError: 'cid'

During handling of the above exception, another exception occurred:

Traceback (most recent call last):
  File "/Users/jiangzhuolin/workspace/python/environment/django_blog_venv/lib/python3.6/site-packages/django/template/base.py", line 883, in _resolve_lookup
    current = current[bit]
  File "/Users/jiangzhuolin/workspace/python/environment/django_blog_venv/lib/python3.6/site-packages/django/utils/datastructures.py", line 85, in __getitem__
    raise MultiValueDictKeyError(repr(key))
django.utils.datastructures.MultiValueDictKeyError: "'cid'"

During handling of the above exception, another exception occurred:

Traceback (most recent call last):
  File "/Users/jiangzhuolin/workspace/python/environment/django_blog_venv/lib/python3.6/site-packages/django/template/base.py", line 891, in _resolve_lookup
    current = getattr(current, bit)
AttributeError: 'QueryDict' object has no attribute 'cid'

During handling of the above exception, another exception occurred:

Traceback (most recent call last):
  File "/Users/jiangzhuolin/workspace/python/environment/django_blog_venv/lib/python3.6/site-packages/django/template/base.py", line 898, in _resolve_lookup
    current = current[int(bit)]
ValueError: invalid literal for int() with base 10: 'cid'

During handling of the above exception, another exception occurred:

Traceback (most recent call last):
  File "/Users/jiangzhuolin/workspace/python/environment/django_blog_venv/lib/python3.6/site-packages/django/template/base.py", line 905, in _resolve_lookup
    (bit, current))  # missing attribute
django.template.base.VariableDoesNotExist: Failed lookup for key [cid] in '<QueryDict: {}>'
2017-04-02 14:56:32,592 [Thread-20:123145361154048] [django.template:927] [base:_resolve_lookup] [DEBUG]- Exception while resolving variable 'year' in template 'index.html'.
Traceback (most recent call last):
  File "/Users/jiangzhuolin/workspace/python/environment/django_blog_venv/lib/python3.6/site-packages/django/utils/datastructures.py", line 83, in __getitem__
    list_ = super(MultiValueDict, self).__getitem__(key)
KeyError: 'year'

During handling of the above exception, another exception occurred:

Traceback (most recent call last):
  File "/Users/jiangzhuolin/workspace/python/environment/django_blog_venv/lib/python3.6/site-packages/django/template/base.py", line 883, in _resolve_lookup
    current = current[bit]
  File "/Users/jiangzhuolin/workspace/python/environment/django_blog_venv/lib/python3.6/site-packages/django/utils/datastructures.py", line 85, in __getitem__
    raise MultiValueDictKeyError(repr(key))
django.utils.datastructures.MultiValueDictKeyError: "'year'"

During handling of the above exception, another exception occurred:

Traceback (most recent call last):
  File "/Users/jiangzhuolin/workspace/python/environment/django_blog_venv/lib/python3.6/site-packages/django/template/base.py", line 891, in _resolve_lookup
    current = getattr(current, bit)
AttributeError: 'QueryDict' object has no attribute 'year'

During handling of the above exception, another exception occurred:

Traceback (most recent call last):
  File "/Users/jiangzhuolin/workspace/python/environment/django_blog_venv/lib/python3.6/site-packages/django/template/base.py", line 898, in _resolve_lookup
    current = current[int(bit)]
ValueError: invalid literal for int() with base 10: 'year'

During handling of the above exception, another exception occurred:

Traceback (most recent call last):
  File "/Users/jiangzhuolin/workspace/python/environment/django_blog_venv/lib/python3.6/site-packages/django/template/base.py", line 905, in _resolve_lookup
    (bit, current))  # missing attribute
django.template.base.VariableDoesNotExist: Failed lookup for key [year] in "<QueryDict: {'cid': ['8']}>"
2017-04-02 14:56:32,593 [Thread-20:123145361154048] [django.template:927] [base:_resolve_lookup] [DEBUG]- Exception while resolving variable 'month' in template 'index.html'.
Traceback (most recent call last):
  File "/Users/jiangzhuolin/workspace/python/environment/django_blog_venv/lib/python3.6/site-packages/django/utils/datastructures.py", line 83, in __getitem__
    list_ = super(MultiValueDict, self).__getitem__(key)
KeyError: 'month'

During handling of the above exception, another exception occurred:

Traceback (most recent call last):
  File "/Users/jiangzhuolin/workspace/python/environment/django_blog_venv/lib/python3.6/site-packages/django/template/base.py", line 883, in _resolve_lookup
    current = current[bit]
  File "/Users/jiangzhuolin/workspace/python/environment/django_blog_venv/lib/python3.6/site-packages/django/utils/datastructures.py", line 85, in __getitem__
    raise MultiValueDictKeyError(repr(key))
django.utils.datastructures.MultiValueDictKeyError: "'month'"

During handling of the above exception, another exception occurred:

Traceback (most recent call last):
  File "/Users/jiangzhuolin/workspace/python/environment/django_blog_venv/lib/python3.6/site-packages/django/template/base.py", line 891, in _resolve_lookup
    current = getattr(current, bit)
AttributeError: 'QueryDict' object has no attribute 'month'

During handling of the above exception, another exception occurred:

Traceback (most recent call last):
  File "/Users/jiangzhuolin/workspace/python/environment/django_blog_venv/lib/python3.6/site-packages/django/template/base.py", line 898, in _resolve_lookup
    current = current[int(bit)]
ValueError: invalid literal for int() with base 10: 'month'

During handling of the above exception, another exception occurred:

Traceback (most recent call last):
  File "/Users/jiangzhuolin/workspace/python/environment/django_blog_venv/lib/python3.6/site-packages/django/template/base.py", line 905, in _resolve_lookup
    (bit, current))  # missing attribute
django.template.base.VariableDoesNotExist: Failed lookup for key [month] in "<QueryDict: {'cid': ['8']}>"
2017-04-02 14:57:32,938 [Thread-22:123145361154048] [django.template:927] [base:_resolve_lookup] [DEBUG]- Exception while resolving variable 'year' in template 'index.html'.
Traceback (most recent call last):
  File "/Users/jiangzhuolin/workspace/python/environment/django_blog_venv/lib/python3.6/site-packages/django/utils/datastructures.py", line 83, in __getitem__
    list_ = super(MultiValueDict, self).__getitem__(key)
KeyError: 'year'

During handling of the above exception, another exception occurred:

Traceback (most recent call last):
  File "/Users/jiangzhuolin/workspace/python/environment/django_blog_venv/lib/python3.6/site-packages/django/template/base.py", line 883, in _resolve_lookup
    current = current[bit]
  File "/Users/jiangzhuolin/workspace/python/environment/django_blog_venv/lib/python3.6/site-packages/django/utils/datastructures.py", line 85, in __getitem__
    raise MultiValueDictKeyError(repr(key))
django.utils.datastructures.MultiValueDictKeyError: "'year'"

During handling of the above exception, another exception occurred:

Traceback (most recent call last):
  File "/Users/jiangzhuolin/workspace/python/environment/django_blog_venv/lib/python3.6/site-packages/django/template/base.py", line 891, in _resolve_lookup
    current = getattr(current, bit)
AttributeError: 'QueryDict' object has no attribute 'year'

During handling of the above exception, another exception occurred:

Traceback (most recent call last):
  File "/Users/jiangzhuolin/workspace/python/environment/django_blog_venv/lib/python3.6/site-packages/django/template/base.py", line 898, in _resolve_lookup
    current = current[int(bit)]
ValueError: invalid literal for int() with base 10: 'year'

During handling of the above exception, another exception occurred:

Traceback (most recent call last):
  File "/Users/jiangzhuolin/workspace/python/environment/django_blog_venv/lib/python3.6/site-packages/django/template/base.py", line 905, in _resolve_lookup
    (bit, current))  # missing attribute
django.template.base.VariableDoesNotExist: Failed lookup for key [year] in '<QueryDict: {}>'
2017-04-02 14:57:32,939 [Thread-22:123145361154048] [django.template:927] [base:_resolve_lookup] [DEBUG]- Exception while resolving variable 'month' in template 'index.html'.
Traceback (most recent call last):
  File "/Users/jiangzhuolin/workspace/python/environment/django_blog_venv/lib/python3.6/site-packages/django/utils/datastructures.py", line 83, in __getitem__
    list_ = super(MultiValueDict, self).__getitem__(key)
KeyError: 'month'

During handling of the above exception, another exception occurred:

Traceback (most recent call last):
  File "/Users/jiangzhuolin/workspace/python/environment/django_blog_venv/lib/python3.6/site-packages/django/template/base.py", line 883, in _resolve_lookup
    current = current[bit]
  File "/Users/jiangzhuolin/workspace/python/environment/django_blog_venv/lib/python3.6/site-packages/django/utils/datastructures.py", line 85, in __getitem__
    raise MultiValueDictKeyError(repr(key))
django.utils.datastructures.MultiValueDictKeyError: "'month'"

During handling of the above exception, another exception occurred:

Traceback (most recent call last):
  File "/Users/jiangzhuolin/workspace/python/environment/django_blog_venv/lib/python3.6/site-packages/django/template/base.py", line 891, in _resolve_lookup
    current = getattr(current, bit)
AttributeError: 'QueryDict' object has no attribute 'month'

During handling of the above exception, another exception occurred:

Traceback (most recent call last):
  File "/Users/jiangzhuolin/workspace/python/environment/django_blog_venv/lib/python3.6/site-packages/django/template/base.py", line 898, in _resolve_lookup
    current = current[int(bit)]
ValueError: invalid literal for int() with base 10: 'month'

During handling of the above exception, another exception occurred:

Traceback (most recent call last):
  File "/Users/jiangzhuolin/workspace/python/environment/django_blog_venv/lib/python3.6/site-packages/django/template/base.py", line 905, in _resolve_lookup
    (bit, current))  # missing attribute
django.template.base.VariableDoesNotExist: Failed lookup for key [month] in '<QueryDict: {}>'
2017-04-02 14:57:32,939 [Thread-22:123145361154048] [django.template:927] [base:_resolve_lookup] [DEBUG]- Exception while resolving variable 'cid' in template 'index.html'.
Traceback (most recent call last):
  File "/Users/jiangzhuolin/workspace/python/environment/django_blog_venv/lib/python3.6/site-packages/django/utils/datastructures.py", line 83, in __getitem__
    list_ = super(MultiValueDict, self).__getitem__(key)
KeyError: 'cid'

During handling of the above exception, another exception occurred:

Traceback (most recent call last):
  File "/Users/jiangzhuolin/workspace/python/environment/django_blog_venv/lib/python3.6/site-packages/django/template/base.py", line 883, in _resolve_lookup
    current = current[bit]
  File "/Users/jiangzhuolin/workspace/python/environment/django_blog_venv/lib/python3.6/site-packages/django/utils/datastructures.py", line 85, in __getitem__
    raise MultiValueDictKeyError(repr(key))
django.utils.datastructures.MultiValueDictKeyError: "'cid'"

During handling of the above exception, another exception occurred:

Traceback (most recent call last):
  File "/Users/jiangzhuolin/workspace/python/environment/django_blog_venv/lib/python3.6/site-packages/django/template/base.py", line 891, in _resolve_lookup
    current = getattr(current, bit)
AttributeError: 'QueryDict' object has no attribute 'cid'

During handling of the above exception, another exception occurred:

Traceback (most recent call last):
  File "/Users/jiangzhuolin/workspace/python/environment/django_blog_venv/lib/python3.6/site-packages/django/template/base.py", line 898, in _resolve_lookup
    current = current[int(bit)]
ValueError: invalid literal for int() with base 10: 'cid'

During handling of the above exception, another exception occurred:

Traceback (most recent call last):
  File "/Users/jiangzhuolin/workspace/python/environment/django_blog_venv/lib/python3.6/site-packages/django/template/base.py", line 905, in _resolve_lookup
    (bit, current))  # missing attribute
django.template.base.VariableDoesNotExist: Failed lookup for key [cid] in '<QueryDict: {}>'
2017-04-02 14:57:34,801 [Thread-23:123145361154048] [django.template:927] [base:_resolve_lookup] [DEBUG]- Exception while resolving variable 'year' in template 'index.html'.
Traceback (most recent call last):
  File "/Users/jiangzhuolin/workspace/python/environment/django_blog_venv/lib/python3.6/site-packages/django/utils/datastructures.py", line 83, in __getitem__
    list_ = super(MultiValueDict, self).__getitem__(key)
KeyError: 'year'

During handling of the above exception, another exception occurred:

Traceback (most recent call last):
  File "/Users/jiangzhuolin/workspace/python/environment/django_blog_venv/lib/python3.6/site-packages/django/template/base.py", line 883, in _resolve_lookup
    current = current[bit]
  File "/Users/jiangzhuolin/workspace/python/environment/django_blog_venv/lib/python3.6/site-packages/django/utils/datastructures.py", line 85, in __getitem__
    raise MultiValueDictKeyError(repr(key))
django.utils.datastructures.MultiValueDictKeyError: "'year'"

During handling of the above exception, another exception occurred:

Traceback (most recent call last):
  File "/Users/jiangzhuolin/workspace/python/environment/django_blog_venv/lib/python3.6/site-packages/django/template/base.py", line 891, in _resolve_lookup
    current = getattr(current, bit)
AttributeError: 'QueryDict' object has no attribute 'year'

During handling of the above exception, another exception occurred:

Traceback (most recent call last):
  File "/Users/jiangzhuolin/workspace/python/environment/django_blog_venv/lib/python3.6/site-packages/django/template/base.py", line 898, in _resolve_lookup
    current = current[int(bit)]
ValueError: invalid literal for int() with base 10: 'year'

During handling of the above exception, another exception occurred:

Traceback (most recent call last):
  File "/Users/jiangzhuolin/workspace/python/environment/django_blog_venv/lib/python3.6/site-packages/django/template/base.py", line 905, in _resolve_lookup
    (bit, current))  # missing attribute
django.template.base.VariableDoesNotExist: Failed lookup for key [year] in '<QueryDict: {}>'
2017-04-02 14:57:34,801 [Thread-23:123145361154048] [django.template:927] [base:_resolve_lookup] [DEBUG]- Exception while resolving variable 'month' in template 'index.html'.
Traceback (most recent call last):
  File "/Users/jiangzhuolin/workspace/python/environment/django_blog_venv/lib/python3.6/site-packages/django/utils/datastructures.py", line 83, in __getitem__
    list_ = super(MultiValueDict, self).__getitem__(key)
KeyError: 'month'

During handling of the above exception, another exception occurred:

Traceback (most recent call last):
  File "/Users/jiangzhuolin/workspace/python/environment/django_blog_venv/lib/python3.6/site-packages/django/template/base.py", line 883, in _resolve_lookup
    current = current[bit]
  File "/Users/jiangzhuolin/workspace/python/environment/django_blog_venv/lib/python3.6/site-packages/django/utils/datastructures.py", line 85, in __getitem__
    raise MultiValueDictKeyError(repr(key))
django.utils.datastructures.MultiValueDictKeyError: "'month'"

During handling of the above exception, another exception occurred:

Traceback (most recent call last):
  File "/Users/jiangzhuolin/workspace/python/environment/django_blog_venv/lib/python3.6/site-packages/django/template/base.py", line 891, in _resolve_lookup
    current = getattr(current, bit)
AttributeError: 'QueryDict' object has no attribute 'month'

During handling of the above exception, another exception occurred:

Traceback (most recent call last):
  File "/Users/jiangzhuolin/workspace/python/environment/django_blog_venv/lib/python3.6/site-packages/django/template/base.py", line 898, in _resolve_lookup
    current = current[int(bit)]
ValueError: invalid literal for int() with base 10: 'month'

During handling of the above exception, another exception occurred:

Traceback (most recent call last):
  File "/Users/jiangzhuolin/workspace/python/environment/django_blog_venv/lib/python3.6/site-packages/django/template/base.py", line 905, in _resolve_lookup
    (bit, current))  # missing attribute
django.template.base.VariableDoesNotExist: Failed lookup for key [month] in '<QueryDict: {}>'
2017-04-02 14:57:34,802 [Thread-23:123145361154048] [django.template:927] [base:_resolve_lookup] [DEBUG]- Exception while resolving variable 'cid' in template 'index.html'.
Traceback (most recent call last):
  File "/Users/jiangzhuolin/workspace/python/environment/django_blog_venv/lib/python3.6/site-packages/django/utils/datastructures.py", line 83, in __getitem__
    list_ = super(MultiValueDict, self).__getitem__(key)
KeyError: 'cid'

During handling of the above exception, another exception occurred:

Traceback (most recent call last):
  File "/Users/jiangzhuolin/workspace/python/environment/django_blog_venv/lib/python3.6/site-packages/django/template/base.py", line 883, in _resolve_lookup
    current = current[bit]
  File "/Users/jiangzhuolin/workspace/python/environment/django_blog_venv/lib/python3.6/site-packages/django/utils/datastructures.py", line 85, in __getitem__
    raise MultiValueDictKeyError(repr(key))
django.utils.datastructures.MultiValueDictKeyError: "'cid'"

During handling of the above exception, another exception occurred:

Traceback (most recent call last):
  File "/Users/jiangzhuolin/workspace/python/environment/django_blog_venv/lib/python3.6/site-packages/django/template/base.py", line 891, in _resolve_lookup
    current = getattr(current, bit)
AttributeError: 'QueryDict' object has no attribute 'cid'

During handling of the above exception, another exception occurred:

Traceback (most recent call last):
  File "/Users/jiangzhuolin/workspace/python/environment/django_blog_venv/lib/python3.6/site-packages/django/template/base.py", line 898, in _resolve_lookup
    current = current[int(bit)]
ValueError: invalid literal for int() with base 10: 'cid'

During handling of the above exception, another exception occurred:

Traceback (most recent call last):
  File "/Users/jiangzhuolin/workspace/python/environment/django_blog_venv/lib/python3.6/site-packages/django/template/base.py", line 905, in _resolve_lookup
    (bit, current))  # missing attribute
django.template.base.VariableDoesNotExist: Failed lookup for key [cid] in '<QueryDict: {}>'
2017-04-02 14:57:36,299 [Thread-24:123145361154048] [django.template:927] [base:_resolve_lookup] [DEBUG]- Exception while resolving variable 'year' in template 'index.html'.
Traceback (most recent call last):
  File "/Users/jiangzhuolin/workspace/python/environment/django_blog_venv/lib/python3.6/site-packages/django/utils/datastructures.py", line 83, in __getitem__
    list_ = super(MultiValueDict, self).__getitem__(key)
KeyError: 'year'

During handling of the above exception, another exception occurred:

Traceback (most recent call last):
  File "/Users/jiangzhuolin/workspace/python/environment/django_blog_venv/lib/python3.6/site-packages/django/template/base.py", line 883, in _resolve_lookup
    current = current[bit]
  File "/Users/jiangzhuolin/workspace/python/environment/django_blog_venv/lib/python3.6/site-packages/django/utils/datastructures.py", line 85, in __getitem__
    raise MultiValueDictKeyError(repr(key))
django.utils.datastructures.MultiValueDictKeyError: "'year'"

During handling of the above exception, another exception occurred:

Traceback (most recent call last):
  File "/Users/jiangzhuolin/workspace/python/environment/django_blog_venv/lib/python3.6/site-packages/django/template/base.py", line 891, in _resolve_lookup
    current = getattr(current, bit)
AttributeError: 'QueryDict' object has no attribute 'year'

During handling of the above exception, another exception occurred:

Traceback (most recent call last):
  File "/Users/jiangzhuolin/workspace/python/environment/django_blog_venv/lib/python3.6/site-packages/django/template/base.py", line 898, in _resolve_lookup
    current = current[int(bit)]
ValueError: invalid literal for int() with base 10: 'year'

During handling of the above exception, another exception occurred:

Traceback (most recent call last):
  File "/Users/jiangzhuolin/workspace/python/environment/django_blog_venv/lib/python3.6/site-packages/django/template/base.py", line 905, in _resolve_lookup
    (bit, current))  # missing attribute
django.template.base.VariableDoesNotExist: Failed lookup for key [year] in '<QueryDict: {}>'
2017-04-02 14:57:36,300 [Thread-24:123145361154048] [django.template:927] [base:_resolve_lookup] [DEBUG]- Exception while resolving variable 'month' in template 'index.html'.
Traceback (most recent call last):
  File "/Users/jiangzhuolin/workspace/python/environment/django_blog_venv/lib/python3.6/site-packages/django/utils/datastructures.py", line 83, in __getitem__
    list_ = super(MultiValueDict, self).__getitem__(key)
KeyError: 'month'

During handling of the above exception, another exception occurred:

Traceback (most recent call last):
  File "/Users/jiangzhuolin/workspace/python/environment/django_blog_venv/lib/python3.6/site-packages/django/template/base.py", line 883, in _resolve_lookup
    current = current[bit]
  File "/Users/jiangzhuolin/workspace/python/environment/django_blog_venv/lib/python3.6/site-packages/django/utils/datastructures.py", line 85, in __getitem__
    raise MultiValueDictKeyError(repr(key))
django.utils.datastructures.MultiValueDictKeyError: "'month'"

During handling of the above exception, another exception occurred:

Traceback (most recent call last):
  File "/Users/jiangzhuolin/workspace/python/environment/django_blog_venv/lib/python3.6/site-packages/django/template/base.py", line 891, in _resolve_lookup
    current = getattr(current, bit)
AttributeError: 'QueryDict' object has no attribute 'month'

During handling of the above exception, another exception occurred:

Traceback (most recent call last):
  File "/Users/jiangzhuolin/workspace/python/environment/django_blog_venv/lib/python3.6/site-packages/django/template/base.py", line 898, in _resolve_lookup
    current = current[int(bit)]
ValueError: invalid literal for int() with base 10: 'month'

During handling of the above exception, another exception occurred:

Traceback (most recent call last):
  File "/Users/jiangzhuolin/workspace/python/environment/django_blog_venv/lib/python3.6/site-packages/django/template/base.py", line 905, in _resolve_lookup
    (bit, current))  # missing attribute
django.template.base.VariableDoesNotExist: Failed lookup for key [month] in '<QueryDict: {}>'
2017-04-02 14:57:36,300 [Thread-24:123145361154048] [django.template:927] [base:_resolve_lookup] [DEBUG]- Exception while resolving variable 'cid' in template 'index.html'.
Traceback (most recent call last):
  File "/Users/jiangzhuolin/workspace/python/environment/django_blog_venv/lib/python3.6/site-packages/django/utils/datastructures.py", line 83, in __getitem__
    list_ = super(MultiValueDict, self).__getitem__(key)
KeyError: 'cid'

During handling of the above exception, another exception occurred:

Traceback (most recent call last):
  File "/Users/jiangzhuolin/workspace/python/environment/django_blog_venv/lib/python3.6/site-packages/django/template/base.py", line 883, in _resolve_lookup
    current = current[bit]
  File "/Users/jiangzhuolin/workspace/python/environment/django_blog_venv/lib/python3.6/site-packages/django/utils/datastructures.py", line 85, in __getitem__
    raise MultiValueDictKeyError(repr(key))
django.utils.datastructures.MultiValueDictKeyError: "'cid'"

During handling of the above exception, another exception occurred:

Traceback (most recent call last):
  File "/Users/jiangzhuolin/workspace/python/environment/django_blog_venv/lib/python3.6/site-packages/django/template/base.py", line 891, in _resolve_lookup
    current = getattr(current, bit)
AttributeError: 'QueryDict' object has no attribute 'cid'

During handling of the above exception, another exception occurred:

Traceback (most recent call last):
  File "/Users/jiangzhuolin/workspace/python/environment/django_blog_venv/lib/python3.6/site-packages/django/template/base.py", line 898, in _resolve_lookup
    current = current[int(bit)]
ValueError: invalid literal for int() with base 10: 'cid'

During handling of the above exception, another exception occurred:

Traceback (most recent call last):
  File "/Users/jiangzhuolin/workspace/python/environment/django_blog_venv/lib/python3.6/site-packages/django/template/base.py", line 905, in _resolve_lookup
    (bit, current))  # missing attribute
django.template.base.VariableDoesNotExist: Failed lookup for key [cid] in '<QueryDict: {}>'
2017-04-02 14:57:37,145 [Thread-25:123145361154048] [django.template:927] [base:_resolve_lookup] [DEBUG]- Exception while resolving variable 'year' in template 'index.html'.
Traceback (most recent call last):
  File "/Users/jiangzhuolin/workspace/python/environment/django_blog_venv/lib/python3.6/site-packages/django/utils/datastructures.py", line 83, in __getitem__
    list_ = super(MultiValueDict, self).__getitem__(key)
KeyError: 'year'

During handling of the above exception, another exception occurred:

Traceback (most recent call last):
  File "/Users/jiangzhuolin/workspace/python/environment/django_blog_venv/lib/python3.6/site-packages/django/template/base.py", line 883, in _resolve_lookup
    current = current[bit]
  File "/Users/jiangzhuolin/workspace/python/environment/django_blog_venv/lib/python3.6/site-packages/django/utils/datastructures.py", line 85, in __getitem__
    raise MultiValueDictKeyError(repr(key))
django.utils.datastructures.MultiValueDictKeyError: "'year'"

During handling of the above exception, another exception occurred:

Traceback (most recent call last):
  File "/Users/jiangzhuolin/workspace/python/environment/django_blog_venv/lib/python3.6/site-packages/django/template/base.py", line 891, in _resolve_lookup
    current = getattr(current, bit)
AttributeError: 'QueryDict' object has no attribute 'year'

During handling of the above exception, another exception occurred:

Traceback (most recent call last):
  File "/Users/jiangzhuolin/workspace/python/environment/django_blog_venv/lib/python3.6/site-packages/django/template/base.py", line 898, in _resolve_lookup
    current = current[int(bit)]
ValueError: invalid literal for int() with base 10: 'year'

During handling of the above exception, another exception occurred:

Traceback (most recent call last):
  File "/Users/jiangzhuolin/workspace/python/environment/django_blog_venv/lib/python3.6/site-packages/django/template/base.py", line 905, in _resolve_lookup
    (bit, current))  # missing attribute
django.template.base.VariableDoesNotExist: Failed lookup for key [year] in '<QueryDict: {}>'
2017-04-02 14:57:37,146 [Thread-25:123145361154048] [django.template:927] [base:_resolve_lookup] [DEBUG]- Exception while resolving variable 'month' in template 'index.html'.
Traceback (most recent call last):
  File "/Users/jiangzhuolin/workspace/python/environment/django_blog_venv/lib/python3.6/site-packages/django/utils/datastructures.py", line 83, in __getitem__
    list_ = super(MultiValueDict, self).__getitem__(key)
KeyError: 'month'

During handling of the above exception, another exception occurred:

Traceback (most recent call last):
  File "/Users/jiangzhuolin/workspace/python/environment/django_blog_venv/lib/python3.6/site-packages/django/template/base.py", line 883, in _resolve_lookup
    current = current[bit]
  File "/Users/jiangzhuolin/workspace/python/environment/django_blog_venv/lib/python3.6/site-packages/django/utils/datastructures.py", line 85, in __getitem__
    raise MultiValueDictKeyError(repr(key))
django.utils.datastructures.MultiValueDictKeyError: "'month'"

During handling of the above exception, another exception occurred:

Traceback (most recent call last):
  File "/Users/jiangzhuolin/workspace/python/environment/django_blog_venv/lib/python3.6/site-packages/django/template/base.py", line 891, in _resolve_lookup
    current = getattr(current, bit)
AttributeError: 'QueryDict' object has no attribute 'month'

During handling of the above exception, another exception occurred:

Traceback (most recent call last):
  File "/Users/jiangzhuolin/workspace/python/environment/django_blog_venv/lib/python3.6/site-packages/django/template/base.py", line 898, in _resolve_lookup
    current = current[int(bit)]
ValueError: invalid literal for int() with base 10: 'month'

During handling of the above exception, another exception occurred:

Traceback (most recent call last):
  File "/Users/jiangzhuolin/workspace/python/environment/django_blog_venv/lib/python3.6/site-packages/django/template/base.py", line 905, in _resolve_lookup
    (bit, current))  # missing attribute
django.template.base.VariableDoesNotExist: Failed lookup for key [month] in '<QueryDict: {}>'
2017-04-02 14:57:37,146 [Thread-25:123145361154048] [django.template:927] [base:_resolve_lookup] [DEBUG]- Exception while resolving variable 'cid' in template 'index.html'.
Traceback (most recent call last):
  File "/Users/jiangzhuolin/workspace/python/environment/django_blog_venv/lib/python3.6/site-packages/django/utils/datastructures.py", line 83, in __getitem__
    list_ = super(MultiValueDict, self).__getitem__(key)
KeyError: 'cid'

During handling of the above exception, another exception occurred:

Traceback (most recent call last):
  File "/Users/jiangzhuolin/workspace/python/environment/django_blog_venv/lib/python3.6/site-packages/django/template/base.py", line 883, in _resolve_lookup
    current = current[bit]
  File "/Users/jiangzhuolin/workspace/python/environment/django_blog_venv/lib/python3.6/site-packages/django/utils/datastructures.py", line 85, in __getitem__
    raise MultiValueDictKeyError(repr(key))
django.utils.datastructures.MultiValueDictKeyError: "'cid'"

During handling of the above exception, another exception occurred:

Traceback (most recent call last):
  File "/Users/jiangzhuolin/workspace/python/environment/django_blog_venv/lib/python3.6/site-packages/django/template/base.py", line 891, in _resolve_lookup
    current = getattr(current, bit)
AttributeError: 'QueryDict' object has no attribute 'cid'

During handling of the above exception, another exception occurred:

Traceback (most recent call last):
  File "/Users/jiangzhuolin/workspace/python/environment/django_blog_venv/lib/python3.6/site-packages/django/template/base.py", line 898, in _resolve_lookup
    current = current[int(bit)]
ValueError: invalid literal for int() with base 10: 'cid'

During handling of the above exception, another exception occurred:

Traceback (most recent call last):
  File "/Users/jiangzhuolin/workspace/python/environment/django_blog_venv/lib/python3.6/site-packages/django/template/base.py", line 905, in _resolve_lookup
    (bit, current))  # missing attribute
django.template.base.VariableDoesNotExist: Failed lookup for key [cid] in '<QueryDict: {}>'
2017-04-02 14:57:40,199 [Thread-26:123145361154048] [django.template:927] [base:_resolve_lookup] [DEBUG]- Exception while resolving variable 'year' in template 'index.html'.
Traceback (most recent call last):
  File "/Users/jiangzhuolin/workspace/python/environment/django_blog_venv/lib/python3.6/site-packages/django/utils/datastructures.py", line 83, in __getitem__
    list_ = super(MultiValueDict, self).__getitem__(key)
KeyError: 'year'

During handling of the above exception, another exception occurred:

Traceback (most recent call last):
  File "/Users/jiangzhuolin/workspace/python/environment/django_blog_venv/lib/python3.6/site-packages/django/template/base.py", line 883, in _resolve_lookup
    current = current[bit]
  File "/Users/jiangzhuolin/workspace/python/environment/django_blog_venv/lib/python3.6/site-packages/django/utils/datastructures.py", line 85, in __getitem__
    raise MultiValueDictKeyError(repr(key))
django.utils.datastructures.MultiValueDictKeyError: "'year'"

During handling of the above exception, another exception occurred:

Traceback (most recent call last):
  File "/Users/jiangzhuolin/workspace/python/environment/django_blog_venv/lib/python3.6/site-packages/django/template/base.py", line 891, in _resolve_lookup
    current = getattr(current, bit)
AttributeError: 'QueryDict' object has no attribute 'year'

During handling of the above exception, another exception occurred:

Traceback (most recent call last):
  File "/Users/jiangzhuolin/workspace/python/environment/django_blog_venv/lib/python3.6/site-packages/django/template/base.py", line 898, in _resolve_lookup
    current = current[int(bit)]
ValueError: invalid literal for int() with base 10: 'year'

During handling of the above exception, another exception occurred:

Traceback (most recent call last):
  File "/Users/jiangzhuolin/workspace/python/environment/django_blog_venv/lib/python3.6/site-packages/django/template/base.py", line 905, in _resolve_lookup
    (bit, current))  # missing attribute
django.template.base.VariableDoesNotExist: Failed lookup for key [year] in '<QueryDict: {}>'
2017-04-02 14:57:40,200 [Thread-26:123145361154048] [django.template:927] [base:_resolve_lookup] [DEBUG]- Exception while resolving variable 'month' in template 'index.html'.
Traceback (most recent call last):
  File "/Users/jiangzhuolin/workspace/python/environment/django_blog_venv/lib/python3.6/site-packages/django/utils/datastructures.py", line 83, in __getitem__
    list_ = super(MultiValueDict, self).__getitem__(key)
KeyError: 'month'

During handling of the above exception, another exception occurred:

Traceback (most recent call last):
  File "/Users/jiangzhuolin/workspace/python/environment/django_blog_venv/lib/python3.6/site-packages/django/template/base.py", line 883, in _resolve_lookup
    current = current[bit]
  File "/Users/jiangzhuolin/workspace/python/environment/django_blog_venv/lib/python3.6/site-packages/django/utils/datastructures.py", line 85, in __getitem__
    raise MultiValueDictKeyError(repr(key))
django.utils.datastructures.MultiValueDictKeyError: "'month'"

During handling of the above exception, another exception occurred:

Traceback (most recent call last):
  File "/Users/jiangzhuolin/workspace/python/environment/django_blog_venv/lib/python3.6/site-packages/django/template/base.py", line 891, in _resolve_lookup
    current = getattr(current, bit)
AttributeError: 'QueryDict' object has no attribute 'month'

During handling of the above exception, another exception occurred:

Traceback (most recent call last):
  File "/Users/jiangzhuolin/workspace/python/environment/django_blog_venv/lib/python3.6/site-packages/django/template/base.py", line 898, in _resolve_lookup
    current = current[int(bit)]
ValueError: invalid literal for int() with base 10: 'month'

During handling of the above exception, another exception occurred:

Traceback (most recent call last):
  File "/Users/jiangzhuolin/workspace/python/environment/django_blog_venv/lib/python3.6/site-packages/django/template/base.py", line 905, in _resolve_lookup
    (bit, current))  # missing attribute
django.template.base.VariableDoesNotExist: Failed lookup for key [month] in '<QueryDict: {}>'
2017-04-02 14:57:40,200 [Thread-26:123145361154048] [django.template:927] [base:_resolve_lookup] [DEBUG]- Exception while resolving variable 'cid' in template 'index.html'.
Traceback (most recent call last):
  File "/Users/jiangzhuolin/workspace/python/environment/django_blog_venv/lib/python3.6/site-packages/django/utils/datastructures.py", line 83, in __getitem__
    list_ = super(MultiValueDict, self).__getitem__(key)
KeyError: 'cid'

During handling of the above exception, another exception occurred:

Traceback (most recent call last):
  File "/Users/jiangzhuolin/workspace/python/environment/django_blog_venv/lib/python3.6/site-packages/django/template/base.py", line 883, in _resolve_lookup
    current = current[bit]
  File "/Users/jiangzhuolin/workspace/python/environment/django_blog_venv/lib/python3.6/site-packages/django/utils/datastructures.py", line 85, in __getitem__
    raise MultiValueDictKeyError(repr(key))
django.utils.datastructures.MultiValueDictKeyError: "'cid'"

During handling of the above exception, another exception occurred:

Traceback (most recent call last):
  File "/Users/jiangzhuolin/workspace/python/environment/django_blog_venv/lib/python3.6/site-packages/django/template/base.py", line 891, in _resolve_lookup
    current = getattr(current, bit)
AttributeError: 'QueryDict' object has no attribute 'cid'

During handling of the above exception, another exception occurred:

Traceback (most recent call last):
  File "/Users/jiangzhuolin/workspace/python/environment/django_blog_venv/lib/python3.6/site-packages/django/template/base.py", line 898, in _resolve_lookup
    current = current[int(bit)]
ValueError: invalid literal for int() with base 10: 'cid'

During handling of the above exception, another exception occurred:

Traceback (most recent call last):
  File "/Users/jiangzhuolin/workspace/python/environment/django_blog_venv/lib/python3.6/site-packages/django/template/base.py", line 905, in _resolve_lookup
    (bit, current))  # missing attribute
django.template.base.VariableDoesNotExist: Failed lookup for key [cid] in '<QueryDict: {}>'
2017-04-02 14:57:41,515 [Thread-27:123145361154048] [django.template:927] [base:_resolve_lookup] [DEBUG]- Exception while resolving variable 'year' in template 'index.html'.
Traceback (most recent call last):
  File "/Users/jiangzhuolin/workspace/python/environment/django_blog_venv/lib/python3.6/site-packages/django/utils/datastructures.py", line 83, in __getitem__
    list_ = super(MultiValueDict, self).__getitem__(key)
KeyError: 'year'

During handling of the above exception, another exception occurred:

Traceback (most recent call last):
  File "/Users/jiangzhuolin/workspace/python/environment/django_blog_venv/lib/python3.6/site-packages/django/template/base.py", line 883, in _resolve_lookup
    current = current[bit]
  File "/Users/jiangzhuolin/workspace/python/environment/django_blog_venv/lib/python3.6/site-packages/django/utils/datastructures.py", line 85, in __getitem__
    raise MultiValueDictKeyError(repr(key))
django.utils.datastructures.MultiValueDictKeyError: "'year'"

During handling of the above exception, another exception occurred:

Traceback (most recent call last):
  File "/Users/jiangzhuolin/workspace/python/environment/django_blog_venv/lib/python3.6/site-packages/django/template/base.py", line 891, in _resolve_lookup
    current = getattr(current, bit)
AttributeError: 'QueryDict' object has no attribute 'year'

During handling of the above exception, another exception occurred:

Traceback (most recent call last):
  File "/Users/jiangzhuolin/workspace/python/environment/django_blog_venv/lib/python3.6/site-packages/django/template/base.py", line 898, in _resolve_lookup
    current = current[int(bit)]
ValueError: invalid literal for int() with base 10: 'year'

During handling of the above exception, another exception occurred:

Traceback (most recent call last):
  File "/Users/jiangzhuolin/workspace/python/environment/django_blog_venv/lib/python3.6/site-packages/django/template/base.py", line 905, in _resolve_lookup
    (bit, current))  # missing attribute
django.template.base.VariableDoesNotExist: Failed lookup for key [year] in '<QueryDict: {}>'
2017-04-02 14:57:41,515 [Thread-27:123145361154048] [django.template:927] [base:_resolve_lookup] [DEBUG]- Exception while resolving variable 'month' in template 'index.html'.
Traceback (most recent call last):
  File "/Users/jiangzhuolin/workspace/python/environment/django_blog_venv/lib/python3.6/site-packages/django/utils/datastructures.py", line 83, in __getitem__
    list_ = super(MultiValueDict, self).__getitem__(key)
KeyError: 'month'

During handling of the above exception, another exception occurred:

Traceback (most recent call last):
  File "/Users/jiangzhuolin/workspace/python/environment/django_blog_venv/lib/python3.6/site-packages/django/template/base.py", line 883, in _resolve_lookup
    current = current[bit]
  File "/Users/jiangzhuolin/workspace/python/environment/django_blog_venv/lib/python3.6/site-packages/django/utils/datastructures.py", line 85, in __getitem__
    raise MultiValueDictKeyError(repr(key))
django.utils.datastructures.MultiValueDictKeyError: "'month'"

During handling of the above exception, another exception occurred:

Traceback (most recent call last):
  File "/Users/jiangzhuolin/workspace/python/environment/django_blog_venv/lib/python3.6/site-packages/django/template/base.py", line 891, in _resolve_lookup
    current = getattr(current, bit)
AttributeError: 'QueryDict' object has no attribute 'month'

During handling of the above exception, another exception occurred:

Traceback (most recent call last):
  File "/Users/jiangzhuolin/workspace/python/environment/django_blog_venv/lib/python3.6/site-packages/django/template/base.py", line 898, in _resolve_lookup
    current = current[int(bit)]
ValueError: invalid literal for int() with base 10: 'month'

During handling of the above exception, another exception occurred:

Traceback (most recent call last):
  File "/Users/jiangzhuolin/workspace/python/environment/django_blog_venv/lib/python3.6/site-packages/django/template/base.py", line 905, in _resolve_lookup
    (bit, current))  # missing attribute
django.template.base.VariableDoesNotExist: Failed lookup for key [month] in '<QueryDict: {}>'
2017-04-02 14:57:41,515 [Thread-27:123145361154048] [django.template:927] [base:_resolve_lookup] [DEBUG]- Exception while resolving variable 'cid' in template 'index.html'.
Traceback (most recent call last):
  File "/Users/jiangzhuolin/workspace/python/environment/django_blog_venv/lib/python3.6/site-packages/django/utils/datastructures.py", line 83, in __getitem__
    list_ = super(MultiValueDict, self).__getitem__(key)
KeyError: 'cid'

During handling of the above exception, another exception occurred:

Traceback (most recent call last):
  File "/Users/jiangzhuolin/workspace/python/environment/django_blog_venv/lib/python3.6/site-packages/django/template/base.py", line 883, in _resolve_lookup
    current = current[bit]
  File "/Users/jiangzhuolin/workspace/python/environment/django_blog_venv/lib/python3.6/site-packages/django/utils/datastructures.py", line 85, in __getitem__
    raise MultiValueDictKeyError(repr(key))
django.utils.datastructures.MultiValueDictKeyError: "'cid'"

During handling of the above exception, another exception occurred:

Traceback (most recent call last):
  File "/Users/jiangzhuolin/workspace/python/environment/django_blog_venv/lib/python3.6/site-packages/django/template/base.py", line 891, in _resolve_lookup
    current = getattr(current, bit)
AttributeError: 'QueryDict' object has no attribute 'cid'

During handling of the above exception, another exception occurred:

Traceback (most recent call last):
  File "/Users/jiangzhuolin/workspace/python/environment/django_blog_venv/lib/python3.6/site-packages/django/template/base.py", line 898, in _resolve_lookup
    current = current[int(bit)]
ValueError: invalid literal for int() with base 10: 'cid'

During handling of the above exception, another exception occurred:

Traceback (most recent call last):
  File "/Users/jiangzhuolin/workspace/python/environment/django_blog_venv/lib/python3.6/site-packages/django/template/base.py", line 905, in _resolve_lookup
    (bit, current))  # missing attribute
django.template.base.VariableDoesNotExist: Failed lookup for key [cid] in '<QueryDict: {}>'
2017-04-02 14:57:42,874 [Thread-28:123145361154048] [django.template:927] [base:_resolve_lookup] [DEBUG]- Exception while resolving variable 'year' in template 'index.html'.
Traceback (most recent call last):
  File "/Users/jiangzhuolin/workspace/python/environment/django_blog_venv/lib/python3.6/site-packages/django/utils/datastructures.py", line 83, in __getitem__
    list_ = super(MultiValueDict, self).__getitem__(key)
KeyError: 'year'

During handling of the above exception, another exception occurred:

Traceback (most recent call last):
  File "/Users/jiangzhuolin/workspace/python/environment/django_blog_venv/lib/python3.6/site-packages/django/template/base.py", line 883, in _resolve_lookup
    current = current[bit]
  File "/Users/jiangzhuolin/workspace/python/environment/django_blog_venv/lib/python3.6/site-packages/django/utils/datastructures.py", line 85, in __getitem__
    raise MultiValueDictKeyError(repr(key))
django.utils.datastructures.MultiValueDictKeyError: "'year'"

During handling of the above exception, another exception occurred:

Traceback (most recent call last):
  File "/Users/jiangzhuolin/workspace/python/environment/django_blog_venv/lib/python3.6/site-packages/django/template/base.py", line 891, in _resolve_lookup
    current = getattr(current, bit)
AttributeError: 'QueryDict' object has no attribute 'year'

During handling of the above exception, another exception occurred:

Traceback (most recent call last):
  File "/Users/jiangzhuolin/workspace/python/environment/django_blog_venv/lib/python3.6/site-packages/django/template/base.py", line 898, in _resolve_lookup
    current = current[int(bit)]
ValueError: invalid literal for int() with base 10: 'year'

During handling of the above exception, another exception occurred:

Traceback (most recent call last):
  File "/Users/jiangzhuolin/workspace/python/environment/django_blog_venv/lib/python3.6/site-packages/django/template/base.py", line 905, in _resolve_lookup
    (bit, current))  # missing attribute
django.template.base.VariableDoesNotExist: Failed lookup for key [year] in '<QueryDict: {}>'
2017-04-02 14:57:42,874 [Thread-28:123145361154048] [django.template:927] [base:_resolve_lookup] [DEBUG]- Exception while resolving variable 'month' in template 'index.html'.
Traceback (most recent call last):
  File "/Users/jiangzhuolin/workspace/python/environment/django_blog_venv/lib/python3.6/site-packages/django/utils/datastructures.py", line 83, in __getitem__
    list_ = super(MultiValueDict, self).__getitem__(key)
KeyError: 'month'

During handling of the above exception, another exception occurred:

Traceback (most recent call last):
  File "/Users/jiangzhuolin/workspace/python/environment/django_blog_venv/lib/python3.6/site-packages/django/template/base.py", line 883, in _resolve_lookup
    current = current[bit]
  File "/Users/jiangzhuolin/workspace/python/environment/django_blog_venv/lib/python3.6/site-packages/django/utils/datastructures.py", line 85, in __getitem__
    raise MultiValueDictKeyError(repr(key))
django.utils.datastructures.MultiValueDictKeyError: "'month'"

During handling of the above exception, another exception occurred:

Traceback (most recent call last):
  File "/Users/jiangzhuolin/workspace/python/environment/django_blog_venv/lib/python3.6/site-packages/django/template/base.py", line 891, in _resolve_lookup
    current = getattr(current, bit)
AttributeError: 'QueryDict' object has no attribute 'month'

During handling of the above exception, another exception occurred:

Traceback (most recent call last):
  File "/Users/jiangzhuolin/workspace/python/environment/django_blog_venv/lib/python3.6/site-packages/django/template/base.py", line 898, in _resolve_lookup
    current = current[int(bit)]
ValueError: invalid literal for int() with base 10: 'month'

During handling of the above exception, another exception occurred:

Traceback (most recent call last):
  File "/Users/jiangzhuolin/workspace/python/environment/django_blog_venv/lib/python3.6/site-packages/django/template/base.py", line 905, in _resolve_lookup
    (bit, current))  # missing attribute
django.template.base.VariableDoesNotExist: Failed lookup for key [month] in '<QueryDict: {}>'
2017-04-02 14:57:42,875 [Thread-28:123145361154048] [django.template:927] [base:_resolve_lookup] [DEBUG]- Exception while resolving variable 'cid' in template 'index.html'.
Traceback (most recent call last):
  File "/Users/jiangzhuolin/workspace/python/environment/django_blog_venv/lib/python3.6/site-packages/django/utils/datastructures.py", line 83, in __getitem__
    list_ = super(MultiValueDict, self).__getitem__(key)
KeyError: 'cid'

During handling of the above exception, another exception occurred:

Traceback (most recent call last):
  File "/Users/jiangzhuolin/workspace/python/environment/django_blog_venv/lib/python3.6/site-packages/django/template/base.py", line 883, in _resolve_lookup
    current = current[bit]
  File "/Users/jiangzhuolin/workspace/python/environment/django_blog_venv/lib/python3.6/site-packages/django/utils/datastructures.py", line 85, in __getitem__
    raise MultiValueDictKeyError(repr(key))
django.utils.datastructures.MultiValueDictKeyError: "'cid'"

During handling of the above exception, another exception occurred:

Traceback (most recent call last):
  File "/Users/jiangzhuolin/workspace/python/environment/django_blog_venv/lib/python3.6/site-packages/django/template/base.py", line 891, in _resolve_lookup
    current = getattr(current, bit)
AttributeError: 'QueryDict' object has no attribute 'cid'

During handling of the above exception, another exception occurred:

Traceback (most recent call last):
  File "/Users/jiangzhuolin/workspace/python/environment/django_blog_venv/lib/python3.6/site-packages/django/template/base.py", line 898, in _resolve_lookup
    current = current[int(bit)]
ValueError: invalid literal for int() with base 10: 'cid'

During handling of the above exception, another exception occurred:

Traceback (most recent call last):
  File "/Users/jiangzhuolin/workspace/python/environment/django_blog_venv/lib/python3.6/site-packages/django/template/base.py", line 905, in _resolve_lookup
    (bit, current))  # missing attribute
django.template.base.VariableDoesNotExist: Failed lookup for key [cid] in '<QueryDict: {}>'
2017-04-02 14:57:43,697 [Thread-29:123145361154048] [django.template:927] [base:_resolve_lookup] [DEBUG]- Exception while resolving variable 'year' in template 'index.html'.
Traceback (most recent call last):
  File "/Users/jiangzhuolin/workspace/python/environment/django_blog_venv/lib/python3.6/site-packages/django/utils/datastructures.py", line 83, in __getitem__
    list_ = super(MultiValueDict, self).__getitem__(key)
KeyError: 'year'

During handling of the above exception, another exception occurred:

Traceback (most recent call last):
  File "/Users/jiangzhuolin/workspace/python/environment/django_blog_venv/lib/python3.6/site-packages/django/template/base.py", line 883, in _resolve_lookup
    current = current[bit]
  File "/Users/jiangzhuolin/workspace/python/environment/django_blog_venv/lib/python3.6/site-packages/django/utils/datastructures.py", line 85, in __getitem__
    raise MultiValueDictKeyError(repr(key))
django.utils.datastructures.MultiValueDictKeyError: "'year'"

During handling of the above exception, another exception occurred:

Traceback (most recent call last):
  File "/Users/jiangzhuolin/workspace/python/environment/django_blog_venv/lib/python3.6/site-packages/django/template/base.py", line 891, in _resolve_lookup
    current = getattr(current, bit)
AttributeError: 'QueryDict' object has no attribute 'year'

During handling of the above exception, another exception occurred:

Traceback (most recent call last):
  File "/Users/jiangzhuolin/workspace/python/environment/django_blog_venv/lib/python3.6/site-packages/django/template/base.py", line 898, in _resolve_lookup
    current = current[int(bit)]
ValueError: invalid literal for int() with base 10: 'year'

During handling of the above exception, another exception occurred:

Traceback (most recent call last):
  File "/Users/jiangzhuolin/workspace/python/environment/django_blog_venv/lib/python3.6/site-packages/django/template/base.py", line 905, in _resolve_lookup
    (bit, current))  # missing attribute
django.template.base.VariableDoesNotExist: Failed lookup for key [year] in '<QueryDict: {}>'
2017-04-02 14:57:43,697 [Thread-29:123145361154048] [django.template:927] [base:_resolve_lookup] [DEBUG]- Exception while resolving variable 'month' in template 'index.html'.
Traceback (most recent call last):
  File "/Users/jiangzhuolin/workspace/python/environment/django_blog_venv/lib/python3.6/site-packages/django/utils/datastructures.py", line 83, in __getitem__
    list_ = super(MultiValueDict, self).__getitem__(key)
KeyError: 'month'

During handling of the above exception, another exception occurred:

Traceback (most recent call last):
  File "/Users/jiangzhuolin/workspace/python/environment/django_blog_venv/lib/python3.6/site-packages/django/template/base.py", line 883, in _resolve_lookup
    current = current[bit]
  File "/Users/jiangzhuolin/workspace/python/environment/django_blog_venv/lib/python3.6/site-packages/django/utils/datastructures.py", line 85, in __getitem__
    raise MultiValueDictKeyError(repr(key))
django.utils.datastructures.MultiValueDictKeyError: "'month'"

During handling of the above exception, another exception occurred:

Traceback (most recent call last):
  File "/Users/jiangzhuolin/workspace/python/environment/django_blog_venv/lib/python3.6/site-packages/django/template/base.py", line 891, in _resolve_lookup
    current = getattr(current, bit)
AttributeError: 'QueryDict' object has no attribute 'month'

During handling of the above exception, another exception occurred:

Traceback (most recent call last):
  File "/Users/jiangzhuolin/workspace/python/environment/django_blog_venv/lib/python3.6/site-packages/django/template/base.py", line 898, in _resolve_lookup
    current = current[int(bit)]
ValueError: invalid literal for int() with base 10: 'month'

During handling of the above exception, another exception occurred:

Traceback (most recent call last):
  File "/Users/jiangzhuolin/workspace/python/environment/django_blog_venv/lib/python3.6/site-packages/django/template/base.py", line 905, in _resolve_lookup
    (bit, current))  # missing attribute
django.template.base.VariableDoesNotExist: Failed lookup for key [month] in '<QueryDict: {}>'
2017-04-02 14:57:43,698 [Thread-29:123145361154048] [django.template:927] [base:_resolve_lookup] [DEBUG]- Exception while resolving variable 'cid' in template 'index.html'.
Traceback (most recent call last):
  File "/Users/jiangzhuolin/workspace/python/environment/django_blog_venv/lib/python3.6/site-packages/django/utils/datastructures.py", line 83, in __getitem__
    list_ = super(MultiValueDict, self).__getitem__(key)
KeyError: 'cid'

During handling of the above exception, another exception occurred:

Traceback (most recent call last):
  File "/Users/jiangzhuolin/workspace/python/environment/django_blog_venv/lib/python3.6/site-packages/django/template/base.py", line 883, in _resolve_lookup
    current = current[bit]
  File "/Users/jiangzhuolin/workspace/python/environment/django_blog_venv/lib/python3.6/site-packages/django/utils/datastructures.py", line 85, in __getitem__
    raise MultiValueDictKeyError(repr(key))
django.utils.datastructures.MultiValueDictKeyError: "'cid'"

During handling of the above exception, another exception occurred:

Traceback (most recent call last):
  File "/Users/jiangzhuolin/workspace/python/environment/django_blog_venv/lib/python3.6/site-packages/django/template/base.py", line 891, in _resolve_lookup
    current = getattr(current, bit)
AttributeError: 'QueryDict' object has no attribute 'cid'

During handling of the above exception, another exception occurred:

Traceback (most recent call last):
  File "/Users/jiangzhuolin/workspace/python/environment/django_blog_venv/lib/python3.6/site-packages/django/template/base.py", line 898, in _resolve_lookup
    current = current[int(bit)]
ValueError: invalid literal for int() with base 10: 'cid'

During handling of the above exception, another exception occurred:

Traceback (most recent call last):
  File "/Users/jiangzhuolin/workspace/python/environment/django_blog_venv/lib/python3.6/site-packages/django/template/base.py", line 905, in _resolve_lookup
    (bit, current))  # missing attribute
django.template.base.VariableDoesNotExist: Failed lookup for key [cid] in '<QueryDict: {}>'
2017-04-02 18:22:34,490 [Thread-33:123145361154048] [django.template:927] [base:_resolve_lookup] [DEBUG]- Exception while resolving variable 'year' in template 'index.html'.
Traceback (most recent call last):
  File "/Users/jiangzhuolin/workspace/python/environment/django_blog_venv/lib/python3.6/site-packages/django/utils/datastructures.py", line 83, in __getitem__
    list_ = super(MultiValueDict, self).__getitem__(key)
KeyError: 'year'

During handling of the above exception, another exception occurred:

Traceback (most recent call last):
  File "/Users/jiangzhuolin/workspace/python/environment/django_blog_venv/lib/python3.6/site-packages/django/template/base.py", line 883, in _resolve_lookup
    current = current[bit]
  File "/Users/jiangzhuolin/workspace/python/environment/django_blog_venv/lib/python3.6/site-packages/django/utils/datastructures.py", line 85, in __getitem__
    raise MultiValueDictKeyError(repr(key))
django.utils.datastructures.MultiValueDictKeyError: "'year'"

During handling of the above exception, another exception occurred:

Traceback (most recent call last):
  File "/Users/jiangzhuolin/workspace/python/environment/django_blog_venv/lib/python3.6/site-packages/django/template/base.py", line 891, in _resolve_lookup
    current = getattr(current, bit)
AttributeError: 'QueryDict' object has no attribute 'year'

During handling of the above exception, another exception occurred:

Traceback (most recent call last):
  File "/Users/jiangzhuolin/workspace/python/environment/django_blog_venv/lib/python3.6/site-packages/django/template/base.py", line 898, in _resolve_lookup
    current = current[int(bit)]
ValueError: invalid literal for int() with base 10: 'year'

During handling of the above exception, another exception occurred:

Traceback (most recent call last):
  File "/Users/jiangzhuolin/workspace/python/environment/django_blog_venv/lib/python3.6/site-packages/django/template/base.py", line 905, in _resolve_lookup
    (bit, current))  # missing attribute
django.template.base.VariableDoesNotExist: Failed lookup for key [year] in "<QueryDict: {'cid': ['8']}>"
2017-04-02 18:22:34,490 [Thread-33:123145361154048] [django.template:927] [base:_resolve_lookup] [DEBUG]- Exception while resolving variable 'month' in template 'index.html'.
Traceback (most recent call last):
  File "/Users/jiangzhuolin/workspace/python/environment/django_blog_venv/lib/python3.6/site-packages/django/utils/datastructures.py", line 83, in __getitem__
    list_ = super(MultiValueDict, self).__getitem__(key)
KeyError: 'month'

During handling of the above exception, another exception occurred:

Traceback (most recent call last):
  File "/Users/jiangzhuolin/workspace/python/environment/django_blog_venv/lib/python3.6/site-packages/django/template/base.py", line 883, in _resolve_lookup
    current = current[bit]
  File "/Users/jiangzhuolin/workspace/python/environment/django_blog_venv/lib/python3.6/site-packages/django/utils/datastructures.py", line 85, in __getitem__
    raise MultiValueDictKeyError(repr(key))
django.utils.datastructures.MultiValueDictKeyError: "'month'"

During handling of the above exception, another exception occurred:

Traceback (most recent call last):
  File "/Users/jiangzhuolin/workspace/python/environment/django_blog_venv/lib/python3.6/site-packages/django/template/base.py", line 891, in _resolve_lookup
    current = getattr(current, bit)
AttributeError: 'QueryDict' object has no attribute 'month'

During handling of the above exception, another exception occurred:

Traceback (most recent call last):
  File "/Users/jiangzhuolin/workspace/python/environment/django_blog_venv/lib/python3.6/site-packages/django/template/base.py", line 898, in _resolve_lookup
    current = current[int(bit)]
ValueError: invalid literal for int() with base 10: 'month'

During handling of the above exception, another exception occurred:

Traceback (most recent call last):
  File "/Users/jiangzhuolin/workspace/python/environment/django_blog_venv/lib/python3.6/site-packages/django/template/base.py", line 905, in _resolve_lookup
    (bit, current))  # missing attribute
django.template.base.VariableDoesNotExist: Failed lookup for key [month] in "<QueryDict: {'cid': ['8']}>"
2017-04-02 18:38:41,462 [Thread-74:123145361154048] [django.template:927] [base:_resolve_lookup] [DEBUG]- Exception while resolving variable 'cid' in template 'index.html'.
Traceback (most recent call last):
  File "/Users/jiangzhuolin/workspace/python/environment/django_blog_venv/lib/python3.6/site-packages/django/utils/datastructures.py", line 83, in __getitem__
    list_ = super(MultiValueDict, self).__getitem__(key)
KeyError: 'cid'

During handling of the above exception, another exception occurred:

Traceback (most recent call last):
  File "/Users/jiangzhuolin/workspace/python/environment/django_blog_venv/lib/python3.6/site-packages/django/template/base.py", line 883, in _resolve_lookup
    current = current[bit]
  File "/Users/jiangzhuolin/workspace/python/environment/django_blog_venv/lib/python3.6/site-packages/django/utils/datastructures.py", line 85, in __getitem__
    raise MultiValueDictKeyError(repr(key))
django.utils.datastructures.MultiValueDictKeyError: "'cid'"

During handling of the above exception, another exception occurred:

Traceback (most recent call last):
  File "/Users/jiangzhuolin/workspace/python/environment/django_blog_venv/lib/python3.6/site-packages/django/template/base.py", line 891, in _resolve_lookup
    current = getattr(current, bit)
AttributeError: 'QueryDict' object has no attribute 'cid'

During handling of the above exception, another exception occurred:

Traceback (most recent call last):
  File "/Users/jiangzhuolin/workspace/python/environment/django_blog_venv/lib/python3.6/site-packages/django/template/base.py", line 898, in _resolve_lookup
    current = current[int(bit)]
ValueError: invalid literal for int() with base 10: 'cid'

During handling of the above exception, another exception occurred:

Traceback (most recent call last):
  File "/Users/jiangzhuolin/workspace/python/environment/django_blog_venv/lib/python3.6/site-packages/django/template/base.py", line 905, in _resolve_lookup
    (bit, current))  # missing attribute
django.template.base.VariableDoesNotExist: Failed lookup for key [cid] in '<QueryDict: {}>'
