2017-03-11 19:08:28,413 [Thread-2:8408] [django.request:182] [base:get_response] [WARNING]- Not Found: /admin/blog/article/1/change/
2017-03-11 23:25:11,049 [Thread-2:3720] [django.request:284] [base:handle_uncaught_exception] [ERROR]- Internal Server Error: /
Traceback (most recent call last):
  File "E:\WorkSpace\django_basic_env\lib\site-packages\django\core\handlers\base.py", line 158, in get_response
    % (callback.__module__, view_name))
ValueError: The view blog.views.index didn't return an HttpResponse object. It returned None instead.
2017-03-12 00:02:14,619 [Thread-13:8572] [django.request:182] [base:get_response] [WARNING]- Not Found: /index.html
2017-03-16 23:08:13,639 [Thread-65:7868] [django.request:284] [base:handle_uncaught_exception] [ERROR]- Internal Server Error: /admin/blog/article/add/
Traceback (most recent call last):
  File "E:\WorkSpace\django_basic_env\lib\site-packages\django\db\backends\utils.py", line 64, in execute
    return self.cursor.execute(sql, params)
  File "E:\WorkSpace\django_basic_env\lib\site-packages\django\db\backends\mysql\base.py", line 112, in execute
    return self.cursor.execute(query, args)
  File "E:\WorkSpace\django_basic_env\lib\site-packages\pymysql\cursors.py", line 166, in execute
    result = self._query(query)
  File "E:\WorkSpace\django_basic_env\lib\site-packages\pymysql\cursors.py", line 322, in _query
    conn.query(q)
  File "E:\WorkSpace\django_basic_env\lib\site-packages\pymysql\connections.py", line 852, in query
    self._affected_rows = self._read_query_result(unbuffered=unbuffered)
  File "E:\WorkSpace\django_basic_env\lib\site-packages\pymysql\connections.py", line 1053, in _read_query_result
    result.read()
  File "E:\WorkSpace\django_basic_env\lib\site-packages\pymysql\connections.py", line 1336, in read
    first_packet = self.connection._read_packet()
  File "E:\WorkSpace\django_basic_env\lib\site-packages\pymysql\connections.py", line 1010, in _read_packet
    packet.check_error()
  File "E:\WorkSpace\django_basic_env\lib\site-packages\pymysql\connections.py", line 393, in check_error
    err.raise_mysql_exception(self._data)
  File "E:\WorkSpace\django_basic_env\lib\site-packages\pymysql\err.py", line 107, in raise_mysql_exception
    raise errorclass(errno, errval)
pymysql.err.IntegrityError: (1048, "Column 'user_id' cannot be null")

The above exception was the direct cause of the following exception:

Traceback (most recent call last):
  File "E:\WorkSpace\django_basic_env\lib\site-packages\django\core\handlers\base.py", line 149, in get_response
    response = self.process_exception_by_middleware(e, request)
  File "E:\WorkSpace\django_basic_env\lib\site-packages\django\core\handlers\base.py", line 147, in get_response
    response = wrapped_callback(request, *callback_args, **callback_kwargs)
  File "E:\WorkSpace\django_basic_env\lib\site-packages\django\contrib\admin\options.py", line 541, in wrapper
    return self.admin_site.admin_view(view)(*args, **kwargs)
  File "E:\WorkSpace\django_basic_env\lib\site-packages\django\utils\decorators.py", line 149, in _wrapped_view
    response = view_func(request, *args, **kwargs)
  File "E:\WorkSpace\django_basic_env\lib\site-packages\django\views\decorators\cache.py", line 57, in _wrapped_view_func
    response = view_func(request, *args, **kwargs)
  File "E:\WorkSpace\django_basic_env\lib\site-packages\django\contrib\admin\sites.py", line 244, in inner
    return view(request, *args, **kwargs)
  File "E:\WorkSpace\django_basic_env\lib\site-packages\django\contrib\admin\options.py", line 1437, in add_view
    return self.changeform_view(request, None, form_url, extra_context)
  File "E:\WorkSpace\django_basic_env\lib\site-packages\django\utils\decorators.py", line 67, in _wrapper
    return bound_func(*args, **kwargs)
  File "E:\WorkSpace\django_basic_env\lib\site-packages\django\utils\decorators.py", line 149, in _wrapped_view
    response = view_func(request, *args, **kwargs)
  File "E:\WorkSpace\django_basic_env\lib\site-packages\django\utils\decorators.py", line 63, in bound_func
    return func.__get__(self, type(self))(*args2, **kwargs2)
  File "c:\program files\python35\Lib\contextlib.py", line 30, in inner
    return func(*args, **kwds)
  File "E:\WorkSpace\django_basic_env\lib\site-packages\django\contrib\admin\options.py", line 1378, in changeform_view
    self.save_model(request, new_object, form, not add)
  File "E:\WorkSpace\django_basic_env\lib\site-packages\django\contrib\admin\options.py", line 991, in save_model
    obj.save()
  File "E:\WorkSpace\django_basic_env\lib\site-packages\django\db\models\base.py", line 708, in save
    force_update=force_update, update_fields=update_fields)
  File "E:\WorkSpace\django_basic_env\lib\site-packages\django\db\models\base.py", line 736, in save_base
    updated = self._save_table(raw, cls, force_insert, force_update, using, update_fields)
  File "E:\WorkSpace\django_basic_env\lib\site-packages\django\db\models\base.py", line 820, in _save_table
    result = self._do_insert(cls._base_manager, using, fields, update_pk, raw)
  File "E:\WorkSpace\django_basic_env\lib\site-packages\django\db\models\base.py", line 859, in _do_insert
    using=using, raw=raw)
  File "E:\WorkSpace\django_basic_env\lib\site-packages\django\db\models\manager.py", line 122, in manager_method
    return getattr(self.get_queryset(), name)(*args, **kwargs)
  File "E:\WorkSpace\django_basic_env\lib\site-packages\django\db\models\query.py", line 1039, in _insert
    return query.get_compiler(using=using).execute_sql(return_id)
  File "E:\WorkSpace\django_basic_env\lib\site-packages\django\db\models\sql\compiler.py", line 1060, in execute_sql
    cursor.execute(sql, params)
  File "E:\WorkSpace\django_basic_env\lib\site-packages\django\db\backends\utils.py", line 79, in execute
    return super(CursorDebugWrapper, self).execute(sql, params)
  File "E:\WorkSpace\django_basic_env\lib\site-packages\django\db\backends\utils.py", line 64, in execute
    return self.cursor.execute(sql, params)
  File "E:\WorkSpace\django_basic_env\lib\site-packages\django\db\utils.py", line 95, in __exit__
    six.reraise(dj_exc_type, dj_exc_value, traceback)
  File "E:\WorkSpace\django_basic_env\lib\site-packages\django\utils\six.py", line 685, in reraise
    raise value.with_traceback(tb)
  File "E:\WorkSpace\django_basic_env\lib\site-packages\django\db\backends\utils.py", line 64, in execute
    return self.cursor.execute(sql, params)
  File "E:\WorkSpace\django_basic_env\lib\site-packages\django\db\backends\mysql\base.py", line 112, in execute
    return self.cursor.execute(query, args)
  File "E:\WorkSpace\django_basic_env\lib\site-packages\pymysql\cursors.py", line 166, in execute
    result = self._query(query)
  File "E:\WorkSpace\django_basic_env\lib\site-packages\pymysql\cursors.py", line 322, in _query
    conn.query(q)
  File "E:\WorkSpace\django_basic_env\lib\site-packages\pymysql\connections.py", line 852, in query
    self._affected_rows = self._read_query_result(unbuffered=unbuffered)
  File "E:\WorkSpace\django_basic_env\lib\site-packages\pymysql\connections.py", line 1053, in _read_query_result
    result.read()
  File "E:\WorkSpace\django_basic_env\lib\site-packages\pymysql\connections.py", line 1336, in read
    first_packet = self.connection._read_packet()
  File "E:\WorkSpace\django_basic_env\lib\site-packages\pymysql\connections.py", line 1010, in _read_packet
    packet.check_error()
  File "E:\WorkSpace\django_basic_env\lib\site-packages\pymysql\connections.py", line 393, in check_error
    err.raise_mysql_exception(self._data)
  File "E:\WorkSpace\django_basic_env\lib\site-packages\pymysql\err.py", line 107, in raise_mysql_exception
    raise errorclass(errno, errval)
django.db.utils.IntegrityError: (1048, "Column 'user_id' cannot be null")
2017-03-16 23:18:44,245 [Thread-54:8016] [django.request:182] [base:get_response] [WARNING]- Not Found: /index.html
2017-03-17 01:53:45,630 [Thread-3:9448] [django.request:284] [base:handle_uncaught_exception] [ERROR]- Internal Server Error: /archive/
Traceback (most recent call last):
  File "E:\WorkSpace\django_basic_env\lib\site-packages\django\core\handlers\base.py", line 158, in get_response
    % (callback.__module__, view_name))
ValueError: The view blog.views.archive didn't return an HttpResponse object. It returned None instead.
2017-03-17 01:59:26,144 [Thread-2:9528] [django.request:284] [base:handle_uncaught_exception] [ERROR]- Internal Server Error: /archive/
Traceback (most recent call last):
  File "E:\WorkSpace\django_basic_env\lib\site-packages\django\core\handlers\base.py", line 158, in get_response
    % (callback.__module__, view_name))
ValueError: The view blog.views.archive didn't return an HttpResponse object. It returned None instead.
2017-03-17 02:21:17,598 [Thread-26:6272] [django.request:182] [base:get_response] [WARNING]- Not Found: /archive/index.html
2017-03-19 20:04:35,270 [Thread-8:6368] [django.request:182] [base:get_response] [WARNING]- Not Found: /archive/index.html
2017-03-19 21:34:30,166 [Thread-2:4552] [django.request:284] [base:handle_uncaught_exception] [ERROR]- Internal Server Error: /archive/
Traceback (most recent call last):
  File "E:\WorkSpace\django_basic_env\lib\site-packages\django\core\handlers\base.py", line 149, in get_response
    response = self.process_exception_by_middleware(e, request)
  File "E:\WorkSpace\django_basic_env\lib\site-packages\django\core\handlers\base.py", line 147, in get_response
    response = wrapped_callback(request, *callback_args, **callback_kwargs)
  File "E:\WorkSpace\Python\my_blog\blog\views.py", line 84, in archive
    return render(request,'archive.html',locals())
  File "E:\WorkSpace\django_basic_env\lib\site-packages\django\shortcuts.py", line 67, in render
    template_name, context, request=request, using=using)
  File "E:\WorkSpace\django_basic_env\lib\site-packages\django\template\loader.py", line 97, in render_to_string
    return template.render(context, request)
  File "E:\WorkSpace\django_basic_env\lib\site-packages\django\template\backends\django.py", line 95, in render
    return self.template.render(context)
  File "E:\WorkSpace\django_basic_env\lib\site-packages\django\template\base.py", line 204, in render
    with context.bind_template(self):
  File "c:\program files\python35\Lib\contextlib.py", line 59, in __enter__
    return next(self.gen)
  File "E:\WorkSpace\django_basic_env\lib\site-packages\django\template\context.py", line 260, in bind_template
    updates.update(processor(self.request))
  File "E:\WorkSpace\Python\my_blog\blog\views.py", line 25, in global_setting
    comment_count_list = Comment.objects.values('article').annotate(comment_count=Count('article').order_by('-comment_count'))
AttributeError: 'Count' object has no attribute 'order_by'
2017-03-19 21:36:51,540 [Thread-2:10504] [django.request:284] [base:handle_uncaught_exception] [ERROR]- Internal Server Error: /
Traceback (most recent call last):
  File "E:\WorkSpace\django_basic_env\lib\site-packages\django\core\handlers\base.py", line 149, in get_response
    response = self.process_exception_by_middleware(e, request)
  File "E:\WorkSpace\django_basic_env\lib\site-packages\django\core\handlers\base.py", line 147, in get_response
    response = wrapped_callback(request, *callback_args, **callback_kwargs)
  File "E:\WorkSpace\Python\my_blog\blog\views.py", line 67, in index
    return render(request, 'index.html', locals())
  File "E:\WorkSpace\django_basic_env\lib\site-packages\django\shortcuts.py", line 67, in render
    template_name, context, request=request, using=using)
  File "E:\WorkSpace\django_basic_env\lib\site-packages\django\template\loader.py", line 97, in render_to_string
    return template.render(context, request)
  File "E:\WorkSpace\django_basic_env\lib\site-packages\django\template\backends\django.py", line 95, in render
    return self.template.render(context)
  File "E:\WorkSpace\django_basic_env\lib\site-packages\django\template\base.py", line 204, in render
    with context.bind_template(self):
  File "c:\program files\python35\Lib\contextlib.py", line 59, in __enter__
    return next(self.gen)
  File "E:\WorkSpace\django_basic_env\lib\site-packages\django\template\context.py", line 260, in bind_template
    updates.update(processor(self.request))
  File "E:\WorkSpace\Python\my_blog\blog\views.py", line 25, in global_setting
    comment_count_list = Comment.objects.values('article').annotate(comment_count=Count('article').order_by('-comment_count'))
AttributeError: 'Count' object has no attribute 'order_by'
2017-03-19 21:39:01,754 [Thread-2:10928] [django.request:284] [base:handle_uncaught_exception] [ERROR]- Internal Server Error: /
Traceback (most recent call last):
  File "E:\WorkSpace\django_basic_env\lib\site-packages\django\core\handlers\base.py", line 149, in get_response
    response = self.process_exception_by_middleware(e, request)
  File "E:\WorkSpace\django_basic_env\lib\site-packages\django\core\handlers\base.py", line 147, in get_response
    response = wrapped_callback(request, *callback_args, **callback_kwargs)
  File "E:\WorkSpace\Python\my_blog\blog\views.py", line 67, in index
    return render(request, 'index.html', locals())
  File "E:\WorkSpace\django_basic_env\lib\site-packages\django\shortcuts.py", line 67, in render
    template_name, context, request=request, using=using)
  File "E:\WorkSpace\django_basic_env\lib\site-packages\django\template\loader.py", line 97, in render_to_string
    return template.render(context, request)
  File "E:\WorkSpace\django_basic_env\lib\site-packages\django\template\backends\django.py", line 95, in render
    return self.template.render(context)
  File "E:\WorkSpace\django_basic_env\lib\site-packages\django\template\base.py", line 204, in render
    with context.bind_template(self):
  File "c:\program files\python35\Lib\contextlib.py", line 59, in __enter__
    return next(self.gen)
  File "E:\WorkSpace\django_basic_env\lib\site-packages\django\template\context.py", line 260, in bind_template
    updates.update(processor(self.request))
  File "E:\WorkSpace\Python\my_blog\blog\views.py", line 26, in global_setting
    print(comment_count_list)
  File "E:\WorkSpace\django_basic_env\lib\site-packages\django\db\models\query.py", line 234, in __repr__
    data = list(self[:REPR_OUTPUT_SIZE + 1])
  File "E:\WorkSpace\django_basic_env\lib\site-packages\django\db\models\query.py", line 258, in __iter__
    self._fetch_all()
  File "E:\WorkSpace\django_basic_env\lib\site-packages\django\db\models\query.py", line 1074, in _fetch_all
    self._result_cache = list(self.iterator())
  File "E:\WorkSpace\django_basic_env\lib\site-packages\django\db\models\query.py", line 112, in __iter__
    for row in compiler.results_iter():
  File "E:\WorkSpace\django_basic_env\lib\site-packages\django\db\models\sql\compiler.py", line 802, in results_iter
    results = self.execute_sql(MULTI)
  File "E:\WorkSpace\django_basic_env\lib\site-packages\django\db\models\sql\compiler.py", line 837, in execute_sql
    sql, params = self.as_sql()
  File "E:\WorkSpace\django_basic_env\lib\site-packages\django\db\models\sql\compiler.py", line 382, in as_sql
    extra_select, order_by, group_by = self.pre_sql_setup()
  File "E:\WorkSpace\django_basic_env\lib\site-packages\django\db\models\sql\compiler.py", line 48, in pre_sql_setup
    self.setup_query()
  File "E:\WorkSpace\django_basic_env\lib\site-packages\django\db\models\sql\compiler.py", line 39, in setup_query
    self.select, self.klass_info, self.annotation_col_map = self.get_select()
  File "E:\WorkSpace\django_basic_env\lib\site-packages\django\db\models\sql\compiler.py", line 228, in get_select
    ret.append((col, self.compile(col, select_format=True), alias))
  File "E:\WorkSpace\django_basic_env\lib\site-packages\django\db\models\sql\compiler.py", line 368, in compile
    return node.output_field.select_format(self, sql, params)
  File "E:\WorkSpace\django_basic_env\lib\site-packages\django\utils\functional.py", line 33, in __get__
    res = instance.__dict__[self.name] = self.func(instance)
  File "E:\WorkSpace\django_basic_env\lib\site-packages\django\db\models\expressions.py", line 228, in output_field
    if self._output_field_or_none is None:
  File "E:\WorkSpace\django_basic_env\lib\site-packages\django\utils\functional.py", line 33, in __get__
    res = instance.__dict__[self.name] = self.func(instance)
  File "E:\WorkSpace\django_basic_env\lib\site-packages\django\db\models\expressions.py", line 240, in _output_field_or_none
    if self._output_field is None:
AttributeError: 'OrderBy' object has no attribute '_output_field'
2017-03-19 21:42:26,687 [Thread-2:3656] [django.request:284] [base:handle_uncaught_exception] [ERROR]- Internal Server Error: /
Traceback (most recent call last):
  File "E:\WorkSpace\django_basic_env\lib\site-packages\django\core\handlers\base.py", line 149, in get_response
    response = self.process_exception_by_middleware(e, request)
  File "E:\WorkSpace\django_basic_env\lib\site-packages\django\core\handlers\base.py", line 147, in get_response
    response = wrapped_callback(request, *callback_args, **callback_kwargs)
  File "E:\WorkSpace\Python\my_blog\blog\views.py", line 68, in index
    return render(request, 'index.html', locals())
  File "E:\WorkSpace\django_basic_env\lib\site-packages\django\shortcuts.py", line 67, in render
    template_name, context, request=request, using=using)
  File "E:\WorkSpace\django_basic_env\lib\site-packages\django\template\loader.py", line 97, in render_to_string
    return template.render(context, request)
  File "E:\WorkSpace\django_basic_env\lib\site-packages\django\template\backends\django.py", line 95, in render
    return self.template.render(context)
  File "E:\WorkSpace\django_basic_env\lib\site-packages\django\template\base.py", line 204, in render
    with context.bind_template(self):
  File "c:\program files\python35\Lib\contextlib.py", line 59, in __enter__
    return next(self.gen)
  File "E:\WorkSpace\django_basic_env\lib\site-packages\django\template\context.py", line 260, in bind_template
    updates.update(processor(self.request))
  File "E:\WorkSpace\Python\my_blog\blog\views.py", line 27, in global_setting
    print(comment_count_list)
  File "E:\WorkSpace\django_basic_env\lib\site-packages\django\db\models\query.py", line 234, in __repr__
    data = list(self[:REPR_OUTPUT_SIZE + 1])
  File "E:\WorkSpace\django_basic_env\lib\site-packages\django\db\models\query.py", line 258, in __iter__
    self._fetch_all()
  File "E:\WorkSpace\django_basic_env\lib\site-packages\django\db\models\query.py", line 1074, in _fetch_all
    self._result_cache = list(self.iterator())
  File "E:\WorkSpace\django_basic_env\lib\site-packages\django\db\models\query.py", line 112, in __iter__
    for row in compiler.results_iter():
  File "E:\WorkSpace\django_basic_env\lib\site-packages\django\db\models\sql\compiler.py", line 802, in results_iter
    results = self.execute_sql(MULTI)
  File "E:\WorkSpace\django_basic_env\lib\site-packages\django\db\models\sql\compiler.py", line 837, in execute_sql
    sql, params = self.as_sql()
  File "E:\WorkSpace\django_basic_env\lib\site-packages\django\db\models\sql\compiler.py", line 382, in as_sql
    extra_select, order_by, group_by = self.pre_sql_setup()
  File "E:\WorkSpace\django_basic_env\lib\site-packages\django\db\models\sql\compiler.py", line 48, in pre_sql_setup
    self.setup_query()
  File "E:\WorkSpace\django_basic_env\lib\site-packages\django\db\models\sql\compiler.py", line 39, in setup_query
    self.select, self.klass_info, self.annotation_col_map = self.get_select()
  File "E:\WorkSpace\django_basic_env\lib\site-packages\django\db\models\sql\compiler.py", line 228, in get_select
    ret.append((col, self.compile(col, select_format=True), alias))
  File "E:\WorkSpace\django_basic_env\lib\site-packages\django\db\models\sql\compiler.py", line 368, in compile
    return node.output_field.select_format(self, sql, params)
  File "E:\WorkSpace\django_basic_env\lib\site-packages\django\utils\functional.py", line 33, in __get__
    res = instance.__dict__[self.name] = self.func(instance)
  File "E:\WorkSpace\django_basic_env\lib\site-packages\django\db\models\expressions.py", line 228, in output_field
    if self._output_field_or_none is None:
  File "E:\WorkSpace\django_basic_env\lib\site-packages\django\utils\functional.py", line 33, in __get__
    res = instance.__dict__[self.name] = self.func(instance)
  File "E:\WorkSpace\django_basic_env\lib\site-packages\django\db\models\expressions.py", line 240, in _output_field_or_none
    if self._output_field is None:
AttributeError: 'OrderBy' object has no attribute '_output_field'
